[12/09/22 10:29:14] 开始导入配置文件...
[12/09/22 10:29:14] 云黑服务器启动...
[12/09/22 10:29:24] 向所有服务器发送同步云黑请求...
[12/09/22 10:29:24] 向服务器127.0.0.1:1111发送请求...
[12/09/22 10:29:26] 服务器连接出错:HTTPConnectionPool(host='127.0.0.1', port=1111): Max retries exceeded with url: /blacklist/sync/ (Caused by NewConnectionError('<urllib3.connection.HTTPConnection object at 0x000001DC1E7A32D0>: Failed to establish a new connection: [WinError 10061] 由于目标计算机积极拒绝，无法连接。'))
Traceback (most recent call last):
  File "C:\Users\zjq13\AppData\Local\Programs\Python\Python311\Lib\site-packages\urllib3\connection.py", line 174, in _new_conn
    conn = connection.create_connection(
           ^^^^^^^^^^^^^^^^^^^^^^^^^^^^^
  File "C:\Users\zjq13\AppData\Local\Programs\Python\Python311\Lib\site-packages\urllib3\util\connection.py", line 95, in create_connection
    raise err
  File "C:\Users\zjq13\AppData\Local\Programs\Python\Python311\Lib\site-packages\urllib3\util\connection.py", line 85, in create_connection
    sock.connect(sa)
ConnectionRefusedError: [WinError 10061] 由于目标计算机积极拒绝，无法连接。

During handling of the above exception, another exception occurred:

Traceback (most recent call last):
  File "C:\Users\zjq13\AppData\Local\Programs\Python\Python311\Lib\site-packages\urllib3\connectionpool.py", line 703, in urlopen
    httplib_response = self._make_request(
                       ^^^^^^^^^^^^^^^^^^^
  File "C:\Users\zjq13\AppData\Local\Programs\Python\Python311\Lib\site-packages\urllib3\connectionpool.py", line 398, in _make_request
    conn.request(method, url, **httplib_request_kw)
  File "C:\Users\zjq13\AppData\Local\Programs\Python\Python311\Lib\site-packages\urllib3\connection.py", line 239, in request
    super(HTTPConnection, self).request(method, url, body=body, headers=headers)
  File "C:\Users\zjq13\AppData\Local\Programs\Python\Python311\Lib\http\client.py", line 1282, in request
    self._send_request(method, url, body, headers, encode_chunked)
  File "C:\Users\zjq13\AppData\Local\Programs\Python\Python311\Lib\http\client.py", line 1328, in _send_request
    self.endheaders(body, encode_chunked=encode_chunked)
  File "C:\Users\zjq13\AppData\Local\Programs\Python\Python311\Lib\http\client.py", line 1277, in endheaders
    self._send_output(message_body, encode_chunked=encode_chunked)
  File "C:\Users\zjq13\AppData\Local\Programs\Python\Python311\Lib\http\client.py", line 1037, in _send_output
    self.send(msg)
  File "C:\Users\zjq13\AppData\Local\Programs\Python\Python311\Lib\http\client.py", line 975, in send
    self.connect()
  File "C:\Users\zjq13\AppData\Local\Programs\Python\Python311\Lib\site-packages\urllib3\connection.py", line 205, in connect
    conn = self._new_conn()
           ^^^^^^^^^^^^^^^^
  File "C:\Users\zjq13\AppData\Local\Programs\Python\Python311\Lib\site-packages\urllib3\connection.py", line 186, in _new_conn
    raise NewConnectionError(
urllib3.exceptions.NewConnectionError: <urllib3.connection.HTTPConnection object at 0x000001DC1E7A32D0>: Failed to establish a new connection: [WinError 10061] 由于目标计算机积极拒绝，无法连接。

During handling of the above exception, another exception occurred:

Traceback (most recent call last):
  File "C:\Users\zjq13\AppData\Local\Programs\Python\Python311\Lib\site-packages\requests\adapters.py", line 489, in send
    resp = conn.urlopen(
           ^^^^^^^^^^^^^
  File "C:\Users\zjq13\AppData\Local\Programs\Python\Python311\Lib\site-packages\urllib3\connectionpool.py", line 787, in urlopen
    retries = retries.increment(
              ^^^^^^^^^^^^^^^^^^
  File "C:\Users\zjq13\AppData\Local\Programs\Python\Python311\Lib\site-packages\urllib3\util\retry.py", line 592, in increment
    raise MaxRetryError(_pool, url, error or ResponseError(cause))
urllib3.exceptions.MaxRetryError: HTTPConnectionPool(host='127.0.0.1', port=1111): Max retries exceeded with url: /blacklist/sync/ (Caused by NewConnectionError('<urllib3.connection.HTTPConnection object at 0x000001DC1E7A32D0>: Failed to establish a new connection: [WinError 10061] 由于目标计算机积极拒绝，无法连接。'))

During handling of the above exception, another exception occurred:

Traceback (most recent call last):
  File "E:\zjq13\Documents\GitHub\bread_dog_bot\blacklist_server\main.py", line 153, in sync_all
    r = get(f"http://{s}/blacklist/sync/")
        ^^^^^^^^^^^^^^^^^^^^^^^^^^^^^^^^^^
  File "C:\Users\zjq13\AppData\Local\Programs\Python\Python311\Lib\site-packages\requests\api.py", line 73, in get
    return request("get", url, params=params, **kwargs)
           ^^^^^^^^^^^^^^^^^^^^^^^^^^^^^^^^^^^^^^^^^^^^
  File "C:\Users\zjq13\AppData\Local\Programs\Python\Python311\Lib\site-packages\requests\api.py", line 59, in request
    return session.request(method=method, url=url, **kwargs)
           ^^^^^^^^^^^^^^^^^^^^^^^^^^^^^^^^^^^^^^^^^^^^^^^^^
  File "C:\Users\zjq13\AppData\Local\Programs\Python\Python311\Lib\site-packages\requests\sessions.py", line 587, in request
    resp = self.send(prep, **send_kwargs)
           ^^^^^^^^^^^^^^^^^^^^^^^^^^^^^^
  File "C:\Users\zjq13\AppData\Local\Programs\Python\Python311\Lib\site-packages\requests\sessions.py", line 701, in send
    r = adapter.send(request, **kwargs)
        ^^^^^^^^^^^^^^^^^^^^^^^^^^^^^^^
  File "C:\Users\zjq13\AppData\Local\Programs\Python\Python311\Lib\site-packages\requests\adapters.py", line 565, in send
    raise ConnectionError(e, request=request)
requests.exceptions.ConnectionError: HTTPConnectionPool(host='127.0.0.1', port=1111): Max retries exceeded with url: /blacklist/sync/ (Caused by NewConnectionError('<urllib3.connection.HTTPConnection object at 0x000001DC1E7A32D0>: Failed to establish a new connection: [WinError 10061] 由于目标计算机积极拒绝，无法连接。'))
[12/09/22 10:29:36] 向所有服务器发送同步云黑请求...
[12/09/22 10:29:36] 向服务器127.0.0.1:1111发送请求...
[12/09/22 10:29:38] 服务器连接出错:HTTPConnectionPool(host='127.0.0.1', port=1111): Max retries exceeded with url: /blacklist/sync/ (Caused by NewConnectionError('<urllib3.connection.HTTPConnection object at 0x000001DC1E854C90>: Failed to establish a new connection: [WinError 10061] 由于目标计算机积极拒绝，无法连接。'))
Traceback (most recent call last):
  File "C:\Users\zjq13\AppData\Local\Programs\Python\Python311\Lib\site-packages\urllib3\connection.py", line 174, in _new_conn
    conn = connection.create_connection(
           ^^^^^^^^^^^^^^^^^^^^^^^^^^^^^
  File "C:\Users\zjq13\AppData\Local\Programs\Python\Python311\Lib\site-packages\urllib3\util\connection.py", line 95, in create_connection
    raise err
  File "C:\Users\zjq13\AppData\Local\Programs\Python\Python311\Lib\site-packages\urllib3\util\connection.py", line 85, in create_connection
    sock.connect(sa)
ConnectionRefusedError: [WinError 10061] 由于目标计算机积极拒绝，无法连接。

During handling of the above exception, another exception occurred:

Traceback (most recent call last):
  File "C:\Users\zjq13\AppData\Local\Programs\Python\Python311\Lib\site-packages\urllib3\connectionpool.py", line 703, in urlopen
    httplib_response = self._make_request(
                       ^^^^^^^^^^^^^^^^^^^
  File "C:\Users\zjq13\AppData\Local\Programs\Python\Python311\Lib\site-packages\urllib3\connectionpool.py", line 398, in _make_request
    conn.request(method, url, **httplib_request_kw)
  File "C:\Users\zjq13\AppData\Local\Programs\Python\Python311\Lib\site-packages\urllib3\connection.py", line 239, in request
    super(HTTPConnection, self).request(method, url, body=body, headers=headers)
  File "C:\Users\zjq13\AppData\Local\Programs\Python\Python311\Lib\http\client.py", line 1282, in request
    self._send_request(method, url, body, headers, encode_chunked)
  File "C:\Users\zjq13\AppData\Local\Programs\Python\Python311\Lib\http\client.py", line 1328, in _send_request
    self.endheaders(body, encode_chunked=encode_chunked)
  File "C:\Users\zjq13\AppData\Local\Programs\Python\Python311\Lib\http\client.py", line 1277, in endheaders
    self._send_output(message_body, encode_chunked=encode_chunked)
  File "C:\Users\zjq13\AppData\Local\Programs\Python\Python311\Lib\http\client.py", line 1037, in _send_output
    self.send(msg)
  File "C:\Users\zjq13\AppData\Local\Programs\Python\Python311\Lib\http\client.py", line 975, in send
    self.connect()
  File "C:\Users\zjq13\AppData\Local\Programs\Python\Python311\Lib\site-packages\urllib3\connection.py", line 205, in connect
    conn = self._new_conn()
           ^^^^^^^^^^^^^^^^
  File "C:\Users\zjq13\AppData\Local\Programs\Python\Python311\Lib\site-packages\urllib3\connection.py", line 186, in _new_conn
    raise NewConnectionError(
urllib3.exceptions.NewConnectionError: <urllib3.connection.HTTPConnection object at 0x000001DC1E854C90>: Failed to establish a new connection: [WinError 10061] 由于目标计算机积极拒绝，无法连接。

During handling of the above exception, another exception occurred:

Traceback (most recent call last):
  File "C:\Users\zjq13\AppData\Local\Programs\Python\Python311\Lib\site-packages\requests\adapters.py", line 489, in send
    resp = conn.urlopen(
           ^^^^^^^^^^^^^
  File "C:\Users\zjq13\AppData\Local\Programs\Python\Python311\Lib\site-packages\urllib3\connectionpool.py", line 787, in urlopen
    retries = retries.increment(
              ^^^^^^^^^^^^^^^^^^
  File "C:\Users\zjq13\AppData\Local\Programs\Python\Python311\Lib\site-packages\urllib3\util\retry.py", line 592, in increment
    raise MaxRetryError(_pool, url, error or ResponseError(cause))
urllib3.exceptions.MaxRetryError: HTTPConnectionPool(host='127.0.0.1', port=1111): Max retries exceeded with url: /blacklist/sync/ (Caused by NewConnectionError('<urllib3.connection.HTTPConnection object at 0x000001DC1E854C90>: Failed to establish a new connection: [WinError 10061] 由于目标计算机积极拒绝，无法连接。'))

During handling of the above exception, another exception occurred:

Traceback (most recent call last):
  File "E:\zjq13\Documents\GitHub\bread_dog_bot\blacklist_server\main.py", line 153, in sync_all
    r = get(f"http://{s}/blacklist/sync/")
        ^^^^^^^^^^^^^^^^^^^^^^^^^^^^^^^^^^
  File "C:\Users\zjq13\AppData\Local\Programs\Python\Python311\Lib\site-packages\requests\api.py", line 73, in get
    return request("get", url, params=params, **kwargs)
           ^^^^^^^^^^^^^^^^^^^^^^^^^^^^^^^^^^^^^^^^^^^^
  File "C:\Users\zjq13\AppData\Local\Programs\Python\Python311\Lib\site-packages\requests\api.py", line 59, in request
    return session.request(method=method, url=url, **kwargs)
           ^^^^^^^^^^^^^^^^^^^^^^^^^^^^^^^^^^^^^^^^^^^^^^^^^
  File "C:\Users\zjq13\AppData\Local\Programs\Python\Python311\Lib\site-packages\requests\sessions.py", line 587, in request
    resp = self.send(prep, **send_kwargs)
           ^^^^^^^^^^^^^^^^^^^^^^^^^^^^^^
  File "C:\Users\zjq13\AppData\Local\Programs\Python\Python311\Lib\site-packages\requests\sessions.py", line 701, in send
    r = adapter.send(request, **kwargs)
        ^^^^^^^^^^^^^^^^^^^^^^^^^^^^^^^
  File "C:\Users\zjq13\AppData\Local\Programs\Python\Python311\Lib\site-packages\requests\adapters.py", line 565, in send
    raise ConnectionError(e, request=request)
requests.exceptions.ConnectionError: HTTPConnectionPool(host='127.0.0.1', port=1111): Max retries exceeded with url: /blacklist/sync/ (Caused by NewConnectionError('<urllib3.connection.HTTPConnection object at 0x000001DC1E854C90>: Failed to establish a new connection: [WinError 10061] 由于目标计算机积极拒绝，无法连接。'))
[12/09/22 10:29:48] 向所有服务器发送同步云黑请求...
[12/09/22 10:29:48] 向服务器127.0.0.1:1111发送请求...
[12/09/22 10:29:50] 服务器连接出错:HTTPConnectionPool(host='127.0.0.1', port=1111): Max retries exceeded with url: /blacklist/sync/ (Caused by NewConnectionError('<urllib3.connection.HTTPConnection object at 0x000001DC1E857390>: Failed to establish a new connection: [WinError 10061] 由于目标计算机积极拒绝，无法连接。'))
Traceback (most recent call last):
  File "C:\Users\zjq13\AppData\Local\Programs\Python\Python311\Lib\site-packages\urllib3\connection.py", line 174, in _new_conn
    conn = connection.create_connection(
           ^^^^^^^^^^^^^^^^^^^^^^^^^^^^^
  File "C:\Users\zjq13\AppData\Local\Programs\Python\Python311\Lib\site-packages\urllib3\util\connection.py", line 95, in create_connection
    raise err
  File "C:\Users\zjq13\AppData\Local\Programs\Python\Python311\Lib\site-packages\urllib3\util\connection.py", line 85, in create_connection
    sock.connect(sa)
ConnectionRefusedError: [WinError 10061] 由于目标计算机积极拒绝，无法连接。

During handling of the above exception, another exception occurred:

Traceback (most recent call last):
  File "C:\Users\zjq13\AppData\Local\Programs\Python\Python311\Lib\site-packages\urllib3\connectionpool.py", line 703, in urlopen
    httplib_response = self._make_request(
                       ^^^^^^^^^^^^^^^^^^^
  File "C:\Users\zjq13\AppData\Local\Programs\Python\Python311\Lib\site-packages\urllib3\connectionpool.py", line 398, in _make_request
    conn.request(method, url, **httplib_request_kw)
  File "C:\Users\zjq13\AppData\Local\Programs\Python\Python311\Lib\site-packages\urllib3\connection.py", line 239, in request
    super(HTTPConnection, self).request(method, url, body=body, headers=headers)
  File "C:\Users\zjq13\AppData\Local\Programs\Python\Python311\Lib\http\client.py", line 1282, in request
    self._send_request(method, url, body, headers, encode_chunked)
  File "C:\Users\zjq13\AppData\Local\Programs\Python\Python311\Lib\http\client.py", line 1328, in _send_request
    self.endheaders(body, encode_chunked=encode_chunked)
  File "C:\Users\zjq13\AppData\Local\Programs\Python\Python311\Lib\http\client.py", line 1277, in endheaders
    self._send_output(message_body, encode_chunked=encode_chunked)
  File "C:\Users\zjq13\AppData\Local\Programs\Python\Python311\Lib\http\client.py", line 1037, in _send_output
    self.send(msg)
  File "C:\Users\zjq13\AppData\Local\Programs\Python\Python311\Lib\http\client.py", line 975, in send
    self.connect()
  File "C:\Users\zjq13\AppData\Local\Programs\Python\Python311\Lib\site-packages\urllib3\connection.py", line 205, in connect
    conn = self._new_conn()
           ^^^^^^^^^^^^^^^^
  File "C:\Users\zjq13\AppData\Local\Programs\Python\Python311\Lib\site-packages\urllib3\connection.py", line 186, in _new_conn
    raise NewConnectionError(
urllib3.exceptions.NewConnectionError: <urllib3.connection.HTTPConnection object at 0x000001DC1E857390>: Failed to establish a new connection: [WinError 10061] 由于目标计算机积极拒绝，无法连接。

During handling of the above exception, another exception occurred:

Traceback (most recent call last):
  File "C:\Users\zjq13\AppData\Local\Programs\Python\Python311\Lib\site-packages\requests\adapters.py", line 489, in send
    resp = conn.urlopen(
           ^^^^^^^^^^^^^
  File "C:\Users\zjq13\AppData\Local\Programs\Python\Python311\Lib\site-packages\urllib3\connectionpool.py", line 787, in urlopen
    retries = retries.increment(
              ^^^^^^^^^^^^^^^^^^
  File "C:\Users\zjq13\AppData\Local\Programs\Python\Python311\Lib\site-packages\urllib3\util\retry.py", line 592, in increment
    raise MaxRetryError(_pool, url, error or ResponseError(cause))
urllib3.exceptions.MaxRetryError: HTTPConnectionPool(host='127.0.0.1', port=1111): Max retries exceeded with url: /blacklist/sync/ (Caused by NewConnectionError('<urllib3.connection.HTTPConnection object at 0x000001DC1E857390>: Failed to establish a new connection: [WinError 10061] 由于目标计算机积极拒绝，无法连接。'))

During handling of the above exception, another exception occurred:

Traceback (most recent call last):
  File "E:\zjq13\Documents\GitHub\bread_dog_bot\blacklist_server\main.py", line 153, in sync_all
    r = get(f"http://{s}/blacklist/sync/")
        ^^^^^^^^^^^^^^^^^^^^^^^^^^^^^^^^^^
  File "C:\Users\zjq13\AppData\Local\Programs\Python\Python311\Lib\site-packages\requests\api.py", line 73, in get
    return request("get", url, params=params, **kwargs)
           ^^^^^^^^^^^^^^^^^^^^^^^^^^^^^^^^^^^^^^^^^^^^
  File "C:\Users\zjq13\AppData\Local\Programs\Python\Python311\Lib\site-packages\requests\api.py", line 59, in request
    return session.request(method=method, url=url, **kwargs)
           ^^^^^^^^^^^^^^^^^^^^^^^^^^^^^^^^^^^^^^^^^^^^^^^^^
  File "C:\Users\zjq13\AppData\Local\Programs\Python\Python311\Lib\site-packages\requests\sessions.py", line 587, in request
    resp = self.send(prep, **send_kwargs)
           ^^^^^^^^^^^^^^^^^^^^^^^^^^^^^^
  File "C:\Users\zjq13\AppData\Local\Programs\Python\Python311\Lib\site-packages\requests\sessions.py", line 701, in send
    r = adapter.send(request, **kwargs)
        ^^^^^^^^^^^^^^^^^^^^^^^^^^^^^^^
  File "C:\Users\zjq13\AppData\Local\Programs\Python\Python311\Lib\site-packages\requests\adapters.py", line 565, in send
    raise ConnectionError(e, request=request)
requests.exceptions.ConnectionError: HTTPConnectionPool(host='127.0.0.1', port=1111): Max retries exceeded with url: /blacklist/sync/ (Caused by NewConnectionError('<urllib3.connection.HTTPConnection object at 0x000001DC1E857390>: Failed to establish a new connection: [WinError 10061] 由于目标计算机积极拒绝，无法连接。'))
[12/09/22 10:30:00] 向所有服务器发送同步云黑请求...
[12/09/22 10:30:00] 向服务器127.0.0.1:1111发送请求...
[12/09/22 10:30:02] 服务器连接出错:HTTPConnectionPool(host='127.0.0.1', port=1111): Max retries exceeded with url: /blacklist/sync/ (Caused by NewConnectionError('<urllib3.connection.HTTPConnection object at 0x000001DC1E861910>: Failed to establish a new connection: [WinError 10061] 由于目标计算机积极拒绝，无法连接。'))
Traceback (most recent call last):
  File "C:\Users\zjq13\AppData\Local\Programs\Python\Python311\Lib\site-packages\urllib3\connection.py", line 174, in _new_conn
    conn = connection.create_connection(
           ^^^^^^^^^^^^^^^^^^^^^^^^^^^^^
  File "C:\Users\zjq13\AppData\Local\Programs\Python\Python311\Lib\site-packages\urllib3\util\connection.py", line 95, in create_connection
    raise err
  File "C:\Users\zjq13\AppData\Local\Programs\Python\Python311\Lib\site-packages\urllib3\util\connection.py", line 85, in create_connection
    sock.connect(sa)
ConnectionRefusedError: [WinError 10061] 由于目标计算机积极拒绝，无法连接。

During handling of the above exception, another exception occurred:

Traceback (most recent call last):
  File "C:\Users\zjq13\AppData\Local\Programs\Python\Python311\Lib\site-packages\urllib3\connectionpool.py", line 703, in urlopen
    httplib_response = self._make_request(
                       ^^^^^^^^^^^^^^^^^^^
  File "C:\Users\zjq13\AppData\Local\Programs\Python\Python311\Lib\site-packages\urllib3\connectionpool.py", line 398, in _make_request
    conn.request(method, url, **httplib_request_kw)
  File "C:\Users\zjq13\AppData\Local\Programs\Python\Python311\Lib\site-packages\urllib3\connection.py", line 239, in request
    super(HTTPConnection, self).request(method, url, body=body, headers=headers)
  File "C:\Users\zjq13\AppData\Local\Programs\Python\Python311\Lib\http\client.py", line 1282, in request
    self._send_request(method, url, body, headers, encode_chunked)
  File "C:\Users\zjq13\AppData\Local\Programs\Python\Python311\Lib\http\client.py", line 1328, in _send_request
    self.endheaders(body, encode_chunked=encode_chunked)
  File "C:\Users\zjq13\AppData\Local\Programs\Python\Python311\Lib\http\client.py", line 1277, in endheaders
    self._send_output(message_body, encode_chunked=encode_chunked)
  File "C:\Users\zjq13\AppData\Local\Programs\Python\Python311\Lib\http\client.py", line 1037, in _send_output
    self.send(msg)
  File "C:\Users\zjq13\AppData\Local\Programs\Python\Python311\Lib\http\client.py", line 975, in send
    self.connect()
  File "C:\Users\zjq13\AppData\Local\Programs\Python\Python311\Lib\site-packages\urllib3\connection.py", line 205, in connect
    conn = self._new_conn()
           ^^^^^^^^^^^^^^^^
  File "C:\Users\zjq13\AppData\Local\Programs\Python\Python311\Lib\site-packages\urllib3\connection.py", line 186, in _new_conn
    raise NewConnectionError(
urllib3.exceptions.NewConnectionError: <urllib3.connection.HTTPConnection object at 0x000001DC1E861910>: Failed to establish a new connection: [WinError 10061] 由于目标计算机积极拒绝，无法连接。

During handling of the above exception, another exception occurred:

Traceback (most recent call last):
  File "C:\Users\zjq13\AppData\Local\Programs\Python\Python311\Lib\site-packages\requests\adapters.py", line 489, in send
    resp = conn.urlopen(
           ^^^^^^^^^^^^^
  File "C:\Users\zjq13\AppData\Local\Programs\Python\Python311\Lib\site-packages\urllib3\connectionpool.py", line 787, in urlopen
    retries = retries.increment(
              ^^^^^^^^^^^^^^^^^^
  File "C:\Users\zjq13\AppData\Local\Programs\Python\Python311\Lib\site-packages\urllib3\util\retry.py", line 592, in increment
    raise MaxRetryError(_pool, url, error or ResponseError(cause))
urllib3.exceptions.MaxRetryError: HTTPConnectionPool(host='127.0.0.1', port=1111): Max retries exceeded with url: /blacklist/sync/ (Caused by NewConnectionError('<urllib3.connection.HTTPConnection object at 0x000001DC1E861910>: Failed to establish a new connection: [WinError 10061] 由于目标计算机积极拒绝，无法连接。'))

During handling of the above exception, another exception occurred:

Traceback (most recent call last):
  File "E:\zjq13\Documents\GitHub\bread_dog_bot\blacklist_server\main.py", line 153, in sync_all
    r = get(f"http://{s}/blacklist/sync/")
        ^^^^^^^^^^^^^^^^^^^^^^^^^^^^^^^^^^
  File "C:\Users\zjq13\AppData\Local\Programs\Python\Python311\Lib\site-packages\requests\api.py", line 73, in get
    return request("get", url, params=params, **kwargs)
           ^^^^^^^^^^^^^^^^^^^^^^^^^^^^^^^^^^^^^^^^^^^^
  File "C:\Users\zjq13\AppData\Local\Programs\Python\Python311\Lib\site-packages\requests\api.py", line 59, in request
    return session.request(method=method, url=url, **kwargs)
           ^^^^^^^^^^^^^^^^^^^^^^^^^^^^^^^^^^^^^^^^^^^^^^^^^
  File "C:\Users\zjq13\AppData\Local\Programs\Python\Python311\Lib\site-packages\requests\sessions.py", line 587, in request
    resp = self.send(prep, **send_kwargs)
           ^^^^^^^^^^^^^^^^^^^^^^^^^^^^^^
  File "C:\Users\zjq13\AppData\Local\Programs\Python\Python311\Lib\site-packages\requests\sessions.py", line 701, in send
    r = adapter.send(request, **kwargs)
        ^^^^^^^^^^^^^^^^^^^^^^^^^^^^^^^
  File "C:\Users\zjq13\AppData\Local\Programs\Python\Python311\Lib\site-packages\requests\adapters.py", line 565, in send
    raise ConnectionError(e, request=request)
requests.exceptions.ConnectionError: HTTPConnectionPool(host='127.0.0.1', port=1111): Max retries exceeded with url: /blacklist/sync/ (Caused by NewConnectionError('<urllib3.connection.HTTPConnection object at 0x000001DC1E861910>: Failed to establish a new connection: [WinError 10061] 由于目标计算机积极拒绝，无法连接。'))
[12/09/22 10:30:12] 向所有服务器发送同步云黑请求...
[12/09/22 10:30:12] 向服务器127.0.0.1:1111发送请求...
[12/09/22 10:30:14] 服务器连接出错:HTTPConnectionPool(host='127.0.0.1', port=1111): Max retries exceeded with url: /blacklist/sync/ (Caused by NewConnectionError('<urllib3.connection.HTTPConnection object at 0x000001DC1E863B50>: Failed to establish a new connection: [WinError 10061] 由于目标计算机积极拒绝，无法连接。'))
Traceback (most recent call last):
  File "C:\Users\zjq13\AppData\Local\Programs\Python\Python311\Lib\site-packages\urllib3\connection.py", line 174, in _new_conn
    conn = connection.create_connection(
           ^^^^^^^^^^^^^^^^^^^^^^^^^^^^^
  File "C:\Users\zjq13\AppData\Local\Programs\Python\Python311\Lib\site-packages\urllib3\util\connection.py", line 95, in create_connection
    raise err
  File "C:\Users\zjq13\AppData\Local\Programs\Python\Python311\Lib\site-packages\urllib3\util\connection.py", line 85, in create_connection
    sock.connect(sa)
ConnectionRefusedError: [WinError 10061] 由于目标计算机积极拒绝，无法连接。

During handling of the above exception, another exception occurred:

Traceback (most recent call last):
  File "C:\Users\zjq13\AppData\Local\Programs\Python\Python311\Lib\site-packages\urllib3\connectionpool.py", line 703, in urlopen
    httplib_response = self._make_request(
                       ^^^^^^^^^^^^^^^^^^^
  File "C:\Users\zjq13\AppData\Local\Programs\Python\Python311\Lib\site-packages\urllib3\connectionpool.py", line 398, in _make_request
    conn.request(method, url, **httplib_request_kw)
  File "C:\Users\zjq13\AppData\Local\Programs\Python\Python311\Lib\site-packages\urllib3\connection.py", line 239, in request
    super(HTTPConnection, self).request(method, url, body=body, headers=headers)
  File "C:\Users\zjq13\AppData\Local\Programs\Python\Python311\Lib\http\client.py", line 1282, in request
    self._send_request(method, url, body, headers, encode_chunked)
  File "C:\Users\zjq13\AppData\Local\Programs\Python\Python311\Lib\http\client.py", line 1328, in _send_request
    self.endheaders(body, encode_chunked=encode_chunked)
  File "C:\Users\zjq13\AppData\Local\Programs\Python\Python311\Lib\http\client.py", line 1277, in endheaders
    self._send_output(message_body, encode_chunked=encode_chunked)
  File "C:\Users\zjq13\AppData\Local\Programs\Python\Python311\Lib\http\client.py", line 1037, in _send_output
    self.send(msg)
  File "C:\Users\zjq13\AppData\Local\Programs\Python\Python311\Lib\http\client.py", line 975, in send
    self.connect()
  File "C:\Users\zjq13\AppData\Local\Programs\Python\Python311\Lib\site-packages\urllib3\connection.py", line 205, in connect
    conn = self._new_conn()
           ^^^^^^^^^^^^^^^^
  File "C:\Users\zjq13\AppData\Local\Programs\Python\Python311\Lib\site-packages\urllib3\connection.py", line 186, in _new_conn
    raise NewConnectionError(
urllib3.exceptions.NewConnectionError: <urllib3.connection.HTTPConnection object at 0x000001DC1E863B50>: Failed to establish a new connection: [WinError 10061] 由于目标计算机积极拒绝，无法连接。

During handling of the above exception, another exception occurred:

Traceback (most recent call last):
  File "C:\Users\zjq13\AppData\Local\Programs\Python\Python311\Lib\site-packages\requests\adapters.py", line 489, in send
    resp = conn.urlopen(
           ^^^^^^^^^^^^^
  File "C:\Users\zjq13\AppData\Local\Programs\Python\Python311\Lib\site-packages\urllib3\connectionpool.py", line 787, in urlopen
    retries = retries.increment(
              ^^^^^^^^^^^^^^^^^^
  File "C:\Users\zjq13\AppData\Local\Programs\Python\Python311\Lib\site-packages\urllib3\util\retry.py", line 592, in increment
    raise MaxRetryError(_pool, url, error or ResponseError(cause))
urllib3.exceptions.MaxRetryError: HTTPConnectionPool(host='127.0.0.1', port=1111): Max retries exceeded with url: /blacklist/sync/ (Caused by NewConnectionError('<urllib3.connection.HTTPConnection object at 0x000001DC1E863B50>: Failed to establish a new connection: [WinError 10061] 由于目标计算机积极拒绝，无法连接。'))

During handling of the above exception, another exception occurred:

Traceback (most recent call last):
  File "E:\zjq13\Documents\GitHub\bread_dog_bot\blacklist_server\main.py", line 153, in sync_all
    r = get(f"http://{s}/blacklist/sync/")
        ^^^^^^^^^^^^^^^^^^^^^^^^^^^^^^^^^^
  File "C:\Users\zjq13\AppData\Local\Programs\Python\Python311\Lib\site-packages\requests\api.py", line 73, in get
    return request("get", url, params=params, **kwargs)
           ^^^^^^^^^^^^^^^^^^^^^^^^^^^^^^^^^^^^^^^^^^^^
  File "C:\Users\zjq13\AppData\Local\Programs\Python\Python311\Lib\site-packages\requests\api.py", line 59, in request
    return session.request(method=method, url=url, **kwargs)
           ^^^^^^^^^^^^^^^^^^^^^^^^^^^^^^^^^^^^^^^^^^^^^^^^^
  File "C:\Users\zjq13\AppData\Local\Programs\Python\Python311\Lib\site-packages\requests\sessions.py", line 587, in request
    resp = self.send(prep, **send_kwargs)
           ^^^^^^^^^^^^^^^^^^^^^^^^^^^^^^
  File "C:\Users\zjq13\AppData\Local\Programs\Python\Python311\Lib\site-packages\requests\sessions.py", line 701, in send
    r = adapter.send(request, **kwargs)
        ^^^^^^^^^^^^^^^^^^^^^^^^^^^^^^^
  File "C:\Users\zjq13\AppData\Local\Programs\Python\Python311\Lib\site-packages\requests\adapters.py", line 565, in send
    raise ConnectionError(e, request=request)
requests.exceptions.ConnectionError: HTTPConnectionPool(host='127.0.0.1', port=1111): Max retries exceeded with url: /blacklist/sync/ (Caused by NewConnectionError('<urllib3.connection.HTTPConnection object at 0x000001DC1E863B50>: Failed to establish a new connection: [WinError 10061] 由于目标计算机积极拒绝，无法连接。'))
[12/09/22 10:30:24] 向所有服务器发送同步云黑请求...
[12/09/22 10:30:24] 向服务器127.0.0.1:1111发送请求...
[12/09/22 10:30:26] 服务器连接出错:HTTPConnectionPool(host='127.0.0.1', port=1111): Max retries exceeded with url: /blacklist/sync/ (Caused by NewConnectionError('<urllib3.connection.HTTPConnection object at 0x000001DC1E86DD90>: Failed to establish a new connection: [WinError 10061] 由于目标计算机积极拒绝，无法连接。'))
Traceback (most recent call last):
  File "C:\Users\zjq13\AppData\Local\Programs\Python\Python311\Lib\site-packages\urllib3\connection.py", line 174, in _new_conn
    conn = connection.create_connection(
           ^^^^^^^^^^^^^^^^^^^^^^^^^^^^^
  File "C:\Users\zjq13\AppData\Local\Programs\Python\Python311\Lib\site-packages\urllib3\util\connection.py", line 95, in create_connection
    raise err
  File "C:\Users\zjq13\AppData\Local\Programs\Python\Python311\Lib\site-packages\urllib3\util\connection.py", line 85, in create_connection
    sock.connect(sa)
ConnectionRefusedError: [WinError 10061] 由于目标计算机积极拒绝，无法连接。

During handling of the above exception, another exception occurred:

Traceback (most recent call last):
  File "C:\Users\zjq13\AppData\Local\Programs\Python\Python311\Lib\site-packages\urllib3\connectionpool.py", line 703, in urlopen
    httplib_response = self._make_request(
                       ^^^^^^^^^^^^^^^^^^^
  File "C:\Users\zjq13\AppData\Local\Programs\Python\Python311\Lib\site-packages\urllib3\connectionpool.py", line 398, in _make_request
    conn.request(method, url, **httplib_request_kw)
  File "C:\Users\zjq13\AppData\Local\Programs\Python\Python311\Lib\site-packages\urllib3\connection.py", line 239, in request
    super(HTTPConnection, self).request(method, url, body=body, headers=headers)
  File "C:\Users\zjq13\AppData\Local\Programs\Python\Python311\Lib\http\client.py", line 1282, in request
    self._send_request(method, url, body, headers, encode_chunked)
  File "C:\Users\zjq13\AppData\Local\Programs\Python\Python311\Lib\http\client.py", line 1328, in _send_request
    self.endheaders(body, encode_chunked=encode_chunked)
  File "C:\Users\zjq13\AppData\Local\Programs\Python\Python311\Lib\http\client.py", line 1277, in endheaders
    self._send_output(message_body, encode_chunked=encode_chunked)
  File "C:\Users\zjq13\AppData\Local\Programs\Python\Python311\Lib\http\client.py", line 1037, in _send_output
    self.send(msg)
  File "C:\Users\zjq13\AppData\Local\Programs\Python\Python311\Lib\http\client.py", line 975, in send
    self.connect()
  File "C:\Users\zjq13\AppData\Local\Programs\Python\Python311\Lib\site-packages\urllib3\connection.py", line 205, in connect
    conn = self._new_conn()
           ^^^^^^^^^^^^^^^^
  File "C:\Users\zjq13\AppData\Local\Programs\Python\Python311\Lib\site-packages\urllib3\connection.py", line 186, in _new_conn
    raise NewConnectionError(
urllib3.exceptions.NewConnectionError: <urllib3.connection.HTTPConnection object at 0x000001DC1E86DD90>: Failed to establish a new connection: [WinError 10061] 由于目标计算机积极拒绝，无法连接。

During handling of the above exception, another exception occurred:

Traceback (most recent call last):
  File "C:\Users\zjq13\AppData\Local\Programs\Python\Python311\Lib\site-packages\requests\adapters.py", line 489, in send
    resp = conn.urlopen(
           ^^^^^^^^^^^^^
  File "C:\Users\zjq13\AppData\Local\Programs\Python\Python311\Lib\site-packages\urllib3\connectionpool.py", line 787, in urlopen
    retries = retries.increment(
              ^^^^^^^^^^^^^^^^^^
  File "C:\Users\zjq13\AppData\Local\Programs\Python\Python311\Lib\site-packages\urllib3\util\retry.py", line 592, in increment
    raise MaxRetryError(_pool, url, error or ResponseError(cause))
urllib3.exceptions.MaxRetryError: HTTPConnectionPool(host='127.0.0.1', port=1111): Max retries exceeded with url: /blacklist/sync/ (Caused by NewConnectionError('<urllib3.connection.HTTPConnection object at 0x000001DC1E86DD90>: Failed to establish a new connection: [WinError 10061] 由于目标计算机积极拒绝，无法连接。'))

During handling of the above exception, another exception occurred:

Traceback (most recent call last):
  File "E:\zjq13\Documents\GitHub\bread_dog_bot\blacklist_server\main.py", line 153, in sync_all
    r = get(f"http://{s}/blacklist/sync/")
        ^^^^^^^^^^^^^^^^^^^^^^^^^^^^^^^^^^
  File "C:\Users\zjq13\AppData\Local\Programs\Python\Python311\Lib\site-packages\requests\api.py", line 73, in get
    return request("get", url, params=params, **kwargs)
           ^^^^^^^^^^^^^^^^^^^^^^^^^^^^^^^^^^^^^^^^^^^^
  File "C:\Users\zjq13\AppData\Local\Programs\Python\Python311\Lib\site-packages\requests\api.py", line 59, in request
    return session.request(method=method, url=url, **kwargs)
           ^^^^^^^^^^^^^^^^^^^^^^^^^^^^^^^^^^^^^^^^^^^^^^^^^
  File "C:\Users\zjq13\AppData\Local\Programs\Python\Python311\Lib\site-packages\requests\sessions.py", line 587, in request
    resp = self.send(prep, **send_kwargs)
           ^^^^^^^^^^^^^^^^^^^^^^^^^^^^^^
  File "C:\Users\zjq13\AppData\Local\Programs\Python\Python311\Lib\site-packages\requests\sessions.py", line 701, in send
    r = adapter.send(request, **kwargs)
        ^^^^^^^^^^^^^^^^^^^^^^^^^^^^^^^
  File "C:\Users\zjq13\AppData\Local\Programs\Python\Python311\Lib\site-packages\requests\adapters.py", line 565, in send
    raise ConnectionError(e, request=request)
requests.exceptions.ConnectionError: HTTPConnectionPool(host='127.0.0.1', port=1111): Max retries exceeded with url: /blacklist/sync/ (Caused by NewConnectionError('<urllib3.connection.HTTPConnection object at 0x000001DC1E86DD90>: Failed to establish a new connection: [WinError 10061] 由于目标计算机积极拒绝，无法连接。'))
[12/09/22 10:30:36] 向所有服务器发送同步云黑请求...
[12/09/22 10:30:36] 向服务器127.0.0.1:1111发送请求...
[12/09/22 10:30:38] 服务器连接出错:HTTPConnectionPool(host='127.0.0.1', port=1111): Max retries exceeded with url: /blacklist/sync/ (Caused by NewConnectionError('<urllib3.connection.HTTPConnection object at 0x000001DC1E8620D0>: Failed to establish a new connection: [WinError 10061] 由于目标计算机积极拒绝，无法连接。'))
Traceback (most recent call last):
  File "C:\Users\zjq13\AppData\Local\Programs\Python\Python311\Lib\site-packages\urllib3\connection.py", line 174, in _new_conn
    conn = connection.create_connection(
           ^^^^^^^^^^^^^^^^^^^^^^^^^^^^^
  File "C:\Users\zjq13\AppData\Local\Programs\Python\Python311\Lib\site-packages\urllib3\util\connection.py", line 95, in create_connection
    raise err
  File "C:\Users\zjq13\AppData\Local\Programs\Python\Python311\Lib\site-packages\urllib3\util\connection.py", line 85, in create_connection
    sock.connect(sa)
ConnectionRefusedError: [WinError 10061] 由于目标计算机积极拒绝，无法连接。

During handling of the above exception, another exception occurred:

Traceback (most recent call last):
  File "C:\Users\zjq13\AppData\Local\Programs\Python\Python311\Lib\site-packages\urllib3\connectionpool.py", line 703, in urlopen
    httplib_response = self._make_request(
                       ^^^^^^^^^^^^^^^^^^^
  File "C:\Users\zjq13\AppData\Local\Programs\Python\Python311\Lib\site-packages\urllib3\connectionpool.py", line 398, in _make_request
    conn.request(method, url, **httplib_request_kw)
  File "C:\Users\zjq13\AppData\Local\Programs\Python\Python311\Lib\site-packages\urllib3\connection.py", line 239, in request
    super(HTTPConnection, self).request(method, url, body=body, headers=headers)
  File "C:\Users\zjq13\AppData\Local\Programs\Python\Python311\Lib\http\client.py", line 1282, in request
    self._send_request(method, url, body, headers, encode_chunked)
  File "C:\Users\zjq13\AppData\Local\Programs\Python\Python311\Lib\http\client.py", line 1328, in _send_request
    self.endheaders(body, encode_chunked=encode_chunked)
  File "C:\Users\zjq13\AppData\Local\Programs\Python\Python311\Lib\http\client.py", line 1277, in endheaders
    self._send_output(message_body, encode_chunked=encode_chunked)
  File "C:\Users\zjq13\AppData\Local\Programs\Python\Python311\Lib\http\client.py", line 1037, in _send_output
    self.send(msg)
  File "C:\Users\zjq13\AppData\Local\Programs\Python\Python311\Lib\http\client.py", line 975, in send
    self.connect()
  File "C:\Users\zjq13\AppData\Local\Programs\Python\Python311\Lib\site-packages\urllib3\connection.py", line 205, in connect
    conn = self._new_conn()
           ^^^^^^^^^^^^^^^^
  File "C:\Users\zjq13\AppData\Local\Programs\Python\Python311\Lib\site-packages\urllib3\connection.py", line 186, in _new_conn
    raise NewConnectionError(
urllib3.exceptions.NewConnectionError: <urllib3.connection.HTTPConnection object at 0x000001DC1E8620D0>: Failed to establish a new connection: [WinError 10061] 由于目标计算机积极拒绝，无法连接。

During handling of the above exception, another exception occurred:

Traceback (most recent call last):
  File "C:\Users\zjq13\AppData\Local\Programs\Python\Python311\Lib\site-packages\requests\adapters.py", line 489, in send
    resp = conn.urlopen(
           ^^^^^^^^^^^^^
  File "C:\Users\zjq13\AppData\Local\Programs\Python\Python311\Lib\site-packages\urllib3\connectionpool.py", line 787, in urlopen
    retries = retries.increment(
              ^^^^^^^^^^^^^^^^^^
  File "C:\Users\zjq13\AppData\Local\Programs\Python\Python311\Lib\site-packages\urllib3\util\retry.py", line 592, in increment
    raise MaxRetryError(_pool, url, error or ResponseError(cause))
urllib3.exceptions.MaxRetryError: HTTPConnectionPool(host='127.0.0.1', port=1111): Max retries exceeded with url: /blacklist/sync/ (Caused by NewConnectionError('<urllib3.connection.HTTPConnection object at 0x000001DC1E8620D0>: Failed to establish a new connection: [WinError 10061] 由于目标计算机积极拒绝，无法连接。'))

During handling of the above exception, another exception occurred:

Traceback (most recent call last):
  File "E:\zjq13\Documents\GitHub\bread_dog_bot\blacklist_server\main.py", line 153, in sync_all
    r = get(f"http://{s}/blacklist/sync/")
        ^^^^^^^^^^^^^^^^^^^^^^^^^^^^^^^^^^
  File "C:\Users\zjq13\AppData\Local\Programs\Python\Python311\Lib\site-packages\requests\api.py", line 73, in get
    return request("get", url, params=params, **kwargs)
           ^^^^^^^^^^^^^^^^^^^^^^^^^^^^^^^^^^^^^^^^^^^^
  File "C:\Users\zjq13\AppData\Local\Programs\Python\Python311\Lib\site-packages\requests\api.py", line 59, in request
    return session.request(method=method, url=url, **kwargs)
           ^^^^^^^^^^^^^^^^^^^^^^^^^^^^^^^^^^^^^^^^^^^^^^^^^
  File "C:\Users\zjq13\AppData\Local\Programs\Python\Python311\Lib\site-packages\requests\sessions.py", line 587, in request
    resp = self.send(prep, **send_kwargs)
           ^^^^^^^^^^^^^^^^^^^^^^^^^^^^^^
  File "C:\Users\zjq13\AppData\Local\Programs\Python\Python311\Lib\site-packages\requests\sessions.py", line 701, in send
    r = adapter.send(request, **kwargs)
        ^^^^^^^^^^^^^^^^^^^^^^^^^^^^^^^
  File "C:\Users\zjq13\AppData\Local\Programs\Python\Python311\Lib\site-packages\requests\adapters.py", line 565, in send
    raise ConnectionError(e, request=request)
requests.exceptions.ConnectionError: HTTPConnectionPool(host='127.0.0.1', port=1111): Max retries exceeded with url: /blacklist/sync/ (Caused by NewConnectionError('<urllib3.connection.HTTPConnection object at 0x000001DC1E8620D0>: Failed to establish a new connection: [WinError 10061] 由于目标计算机积极拒绝，无法连接。'))
[12/09/22 10:30:48] 向所有服务器发送同步云黑请求...
[12/09/22 10:30:48] 向服务器127.0.0.1:1111发送请求...
[12/09/22 10:30:50] 服务器连接出错:HTTPConnectionPool(host='127.0.0.1', port=1111): Max retries exceeded with url: /blacklist/sync/ (Caused by NewConnectionError('<urllib3.connection.HTTPConnection object at 0x000001DC1E856D50>: Failed to establish a new connection: [WinError 10061] 由于目标计算机积极拒绝，无法连接。'))
Traceback (most recent call last):
  File "C:\Users\zjq13\AppData\Local\Programs\Python\Python311\Lib\site-packages\urllib3\connection.py", line 174, in _new_conn
    conn = connection.create_connection(
           ^^^^^^^^^^^^^^^^^^^^^^^^^^^^^
  File "C:\Users\zjq13\AppData\Local\Programs\Python\Python311\Lib\site-packages\urllib3\util\connection.py", line 95, in create_connection
    raise err
  File "C:\Users\zjq13\AppData\Local\Programs\Python\Python311\Lib\site-packages\urllib3\util\connection.py", line 85, in create_connection
    sock.connect(sa)
ConnectionRefusedError: [WinError 10061] 由于目标计算机积极拒绝，无法连接。

During handling of the above exception, another exception occurred:

Traceback (most recent call last):
  File "C:\Users\zjq13\AppData\Local\Programs\Python\Python311\Lib\site-packages\urllib3\connectionpool.py", line 703, in urlopen
    httplib_response = self._make_request(
                       ^^^^^^^^^^^^^^^^^^^
  File "C:\Users\zjq13\AppData\Local\Programs\Python\Python311\Lib\site-packages\urllib3\connectionpool.py", line 398, in _make_request
    conn.request(method, url, **httplib_request_kw)
  File "C:\Users\zjq13\AppData\Local\Programs\Python\Python311\Lib\site-packages\urllib3\connection.py", line 239, in request
    super(HTTPConnection, self).request(method, url, body=body, headers=headers)
  File "C:\Users\zjq13\AppData\Local\Programs\Python\Python311\Lib\http\client.py", line 1282, in request
    self._send_request(method, url, body, headers, encode_chunked)
  File "C:\Users\zjq13\AppData\Local\Programs\Python\Python311\Lib\http\client.py", line 1328, in _send_request
    self.endheaders(body, encode_chunked=encode_chunked)
  File "C:\Users\zjq13\AppData\Local\Programs\Python\Python311\Lib\http\client.py", line 1277, in endheaders
    self._send_output(message_body, encode_chunked=encode_chunked)
  File "C:\Users\zjq13\AppData\Local\Programs\Python\Python311\Lib\http\client.py", line 1037, in _send_output
    self.send(msg)
  File "C:\Users\zjq13\AppData\Local\Programs\Python\Python311\Lib\http\client.py", line 975, in send
    self.connect()
  File "C:\Users\zjq13\AppData\Local\Programs\Python\Python311\Lib\site-packages\urllib3\connection.py", line 205, in connect
    conn = self._new_conn()
           ^^^^^^^^^^^^^^^^
  File "C:\Users\zjq13\AppData\Local\Programs\Python\Python311\Lib\site-packages\urllib3\connection.py", line 186, in _new_conn
    raise NewConnectionError(
urllib3.exceptions.NewConnectionError: <urllib3.connection.HTTPConnection object at 0x000001DC1E856D50>: Failed to establish a new connection: [WinError 10061] 由于目标计算机积极拒绝，无法连接。

During handling of the above exception, another exception occurred:

Traceback (most recent call last):
  File "C:\Users\zjq13\AppData\Local\Programs\Python\Python311\Lib\site-packages\requests\adapters.py", line 489, in send
    resp = conn.urlopen(
           ^^^^^^^^^^^^^
  File "C:\Users\zjq13\AppData\Local\Programs\Python\Python311\Lib\site-packages\urllib3\connectionpool.py", line 787, in urlopen
    retries = retries.increment(
              ^^^^^^^^^^^^^^^^^^
  File "C:\Users\zjq13\AppData\Local\Programs\Python\Python311\Lib\site-packages\urllib3\util\retry.py", line 592, in increment
    raise MaxRetryError(_pool, url, error or ResponseError(cause))
urllib3.exceptions.MaxRetryError: HTTPConnectionPool(host='127.0.0.1', port=1111): Max retries exceeded with url: /blacklist/sync/ (Caused by NewConnectionError('<urllib3.connection.HTTPConnection object at 0x000001DC1E856D50>: Failed to establish a new connection: [WinError 10061] 由于目标计算机积极拒绝，无法连接。'))

During handling of the above exception, another exception occurred:

Traceback (most recent call last):
  File "E:\zjq13\Documents\GitHub\bread_dog_bot\blacklist_server\main.py", line 153, in sync_all
    r = get(f"http://{s}/blacklist/sync/")
        ^^^^^^^^^^^^^^^^^^^^^^^^^^^^^^^^^^
  File "C:\Users\zjq13\AppData\Local\Programs\Python\Python311\Lib\site-packages\requests\api.py", line 73, in get
    return request("get", url, params=params, **kwargs)
           ^^^^^^^^^^^^^^^^^^^^^^^^^^^^^^^^^^^^^^^^^^^^
  File "C:\Users\zjq13\AppData\Local\Programs\Python\Python311\Lib\site-packages\requests\api.py", line 59, in request
    return session.request(method=method, url=url, **kwargs)
           ^^^^^^^^^^^^^^^^^^^^^^^^^^^^^^^^^^^^^^^^^^^^^^^^^
  File "C:\Users\zjq13\AppData\Local\Programs\Python\Python311\Lib\site-packages\requests\sessions.py", line 587, in request
    resp = self.send(prep, **send_kwargs)
           ^^^^^^^^^^^^^^^^^^^^^^^^^^^^^^
  File "C:\Users\zjq13\AppData\Local\Programs\Python\Python311\Lib\site-packages\requests\sessions.py", line 701, in send
    r = adapter.send(request, **kwargs)
        ^^^^^^^^^^^^^^^^^^^^^^^^^^^^^^^
  File "C:\Users\zjq13\AppData\Local\Programs\Python\Python311\Lib\site-packages\requests\adapters.py", line 565, in send
    raise ConnectionError(e, request=request)
requests.exceptions.ConnectionError: HTTPConnectionPool(host='127.0.0.1', port=1111): Max retries exceeded with url: /blacklist/sync/ (Caused by NewConnectionError('<urllib3.connection.HTTPConnection object at 0x000001DC1E856D50>: Failed to establish a new connection: [WinError 10061] 由于目标计算机积极拒绝，无法连接。'))
[12/09/22 10:31:00] 向所有服务器发送同步云黑请求...
[12/09/22 10:31:00] 向服务器127.0.0.1:1111发送请求...
[12/09/22 10:31:02] 服务器连接出错:HTTPConnectionPool(host='127.0.0.1', port=1111): Max retries exceeded with url: /blacklist/sync/ (Caused by NewConnectionError('<urllib3.connection.HTTPConnection object at 0x000001DC1E855010>: Failed to establish a new connection: [WinError 10061] 由于目标计算机积极拒绝，无法连接。'))
Traceback (most recent call last):
  File "C:\Users\zjq13\AppData\Local\Programs\Python\Python311\Lib\site-packages\urllib3\connection.py", line 174, in _new_conn
    conn = connection.create_connection(
           ^^^^^^^^^^^^^^^^^^^^^^^^^^^^^
  File "C:\Users\zjq13\AppData\Local\Programs\Python\Python311\Lib\site-packages\urllib3\util\connection.py", line 95, in create_connection
    raise err
  File "C:\Users\zjq13\AppData\Local\Programs\Python\Python311\Lib\site-packages\urllib3\util\connection.py", line 85, in create_connection
    sock.connect(sa)
ConnectionRefusedError: [WinError 10061] 由于目标计算机积极拒绝，无法连接。

During handling of the above exception, another exception occurred:

Traceback (most recent call last):
  File "C:\Users\zjq13\AppData\Local\Programs\Python\Python311\Lib\site-packages\urllib3\connectionpool.py", line 703, in urlopen
    httplib_response = self._make_request(
                       ^^^^^^^^^^^^^^^^^^^
  File "C:\Users\zjq13\AppData\Local\Programs\Python\Python311\Lib\site-packages\urllib3\connectionpool.py", line 398, in _make_request
    conn.request(method, url, **httplib_request_kw)
  File "C:\Users\zjq13\AppData\Local\Programs\Python\Python311\Lib\site-packages\urllib3\connection.py", line 239, in request
    super(HTTPConnection, self).request(method, url, body=body, headers=headers)
  File "C:\Users\zjq13\AppData\Local\Programs\Python\Python311\Lib\http\client.py", line 1282, in request
    self._send_request(method, url, body, headers, encode_chunked)
  File "C:\Users\zjq13\AppData\Local\Programs\Python\Python311\Lib\http\client.py", line 1328, in _send_request
    self.endheaders(body, encode_chunked=encode_chunked)
  File "C:\Users\zjq13\AppData\Local\Programs\Python\Python311\Lib\http\client.py", line 1277, in endheaders
    self._send_output(message_body, encode_chunked=encode_chunked)
  File "C:\Users\zjq13\AppData\Local\Programs\Python\Python311\Lib\http\client.py", line 1037, in _send_output
    self.send(msg)
  File "C:\Users\zjq13\AppData\Local\Programs\Python\Python311\Lib\http\client.py", line 975, in send
    self.connect()
  File "C:\Users\zjq13\AppData\Local\Programs\Python\Python311\Lib\site-packages\urllib3\connection.py", line 205, in connect
    conn = self._new_conn()
           ^^^^^^^^^^^^^^^^
  File "C:\Users\zjq13\AppData\Local\Programs\Python\Python311\Lib\site-packages\urllib3\connection.py", line 186, in _new_conn
    raise NewConnectionError(
urllib3.exceptions.NewConnectionError: <urllib3.connection.HTTPConnection object at 0x000001DC1E855010>: Failed to establish a new connection: [WinError 10061] 由于目标计算机积极拒绝，无法连接。

During handling of the above exception, another exception occurred:

Traceback (most recent call last):
  File "C:\Users\zjq13\AppData\Local\Programs\Python\Python311\Lib\site-packages\requests\adapters.py", line 489, in send
    resp = conn.urlopen(
           ^^^^^^^^^^^^^
  File "C:\Users\zjq13\AppData\Local\Programs\Python\Python311\Lib\site-packages\urllib3\connectionpool.py", line 787, in urlopen
    retries = retries.increment(
              ^^^^^^^^^^^^^^^^^^
  File "C:\Users\zjq13\AppData\Local\Programs\Python\Python311\Lib\site-packages\urllib3\util\retry.py", line 592, in increment
    raise MaxRetryError(_pool, url, error or ResponseError(cause))
urllib3.exceptions.MaxRetryError: HTTPConnectionPool(host='127.0.0.1', port=1111): Max retries exceeded with url: /blacklist/sync/ (Caused by NewConnectionError('<urllib3.connection.HTTPConnection object at 0x000001DC1E855010>: Failed to establish a new connection: [WinError 10061] 由于目标计算机积极拒绝，无法连接。'))

During handling of the above exception, another exception occurred:

Traceback (most recent call last):
  File "E:\zjq13\Documents\GitHub\bread_dog_bot\blacklist_server\main.py", line 153, in sync_all
    r = get(f"http://{s}/blacklist/sync/")
        ^^^^^^^^^^^^^^^^^^^^^^^^^^^^^^^^^^
  File "C:\Users\zjq13\AppData\Local\Programs\Python\Python311\Lib\site-packages\requests\api.py", line 73, in get
    return request("get", url, params=params, **kwargs)
           ^^^^^^^^^^^^^^^^^^^^^^^^^^^^^^^^^^^^^^^^^^^^
  File "C:\Users\zjq13\AppData\Local\Programs\Python\Python311\Lib\site-packages\requests\api.py", line 59, in request
    return session.request(method=method, url=url, **kwargs)
           ^^^^^^^^^^^^^^^^^^^^^^^^^^^^^^^^^^^^^^^^^^^^^^^^^
  File "C:\Users\zjq13\AppData\Local\Programs\Python\Python311\Lib\site-packages\requests\sessions.py", line 587, in request
    resp = self.send(prep, **send_kwargs)
           ^^^^^^^^^^^^^^^^^^^^^^^^^^^^^^
  File "C:\Users\zjq13\AppData\Local\Programs\Python\Python311\Lib\site-packages\requests\sessions.py", line 701, in send
    r = adapter.send(request, **kwargs)
        ^^^^^^^^^^^^^^^^^^^^^^^^^^^^^^^
  File "C:\Users\zjq13\AppData\Local\Programs\Python\Python311\Lib\site-packages\requests\adapters.py", line 565, in send
    raise ConnectionError(e, request=request)
requests.exceptions.ConnectionError: HTTPConnectionPool(host='127.0.0.1', port=1111): Max retries exceeded with url: /blacklist/sync/ (Caused by NewConnectionError('<urllib3.connection.HTTPConnection object at 0x000001DC1E855010>: Failed to establish a new connection: [WinError 10061] 由于目标计算机积极拒绝，无法连接。'))
[12/09/22 10:31:12] 向所有服务器发送同步云黑请求...
[12/09/22 10:31:12] 向服务器127.0.0.1:1111发送请求...
[12/09/22 10:31:14] 服务器连接出错:HTTPConnectionPool(host='127.0.0.1', port=1111): Max retries exceeded with url: /blacklist/sync/ (Caused by NewConnectionError('<urllib3.connection.HTTPConnection object at 0x000001DC1E86EA90>: Failed to establish a new connection: [WinError 10061] 由于目标计算机积极拒绝，无法连接。'))
Traceback (most recent call last):
  File "C:\Users\zjq13\AppData\Local\Programs\Python\Python311\Lib\site-packages\urllib3\connection.py", line 174, in _new_conn
    conn = connection.create_connection(
           ^^^^^^^^^^^^^^^^^^^^^^^^^^^^^
  File "C:\Users\zjq13\AppData\Local\Programs\Python\Python311\Lib\site-packages\urllib3\util\connection.py", line 95, in create_connection
    raise err
  File "C:\Users\zjq13\AppData\Local\Programs\Python\Python311\Lib\site-packages\urllib3\util\connection.py", line 85, in create_connection
    sock.connect(sa)
ConnectionRefusedError: [WinError 10061] 由于目标计算机积极拒绝，无法连接。

During handling of the above exception, another exception occurred:

Traceback (most recent call last):
  File "C:\Users\zjq13\AppData\Local\Programs\Python\Python311\Lib\site-packages\urllib3\connectionpool.py", line 703, in urlopen
    httplib_response = self._make_request(
                       ^^^^^^^^^^^^^^^^^^^
  File "C:\Users\zjq13\AppData\Local\Programs\Python\Python311\Lib\site-packages\urllib3\connectionpool.py", line 398, in _make_request
    conn.request(method, url, **httplib_request_kw)
  File "C:\Users\zjq13\AppData\Local\Programs\Python\Python311\Lib\site-packages\urllib3\connection.py", line 239, in request
    super(HTTPConnection, self).request(method, url, body=body, headers=headers)
  File "C:\Users\zjq13\AppData\Local\Programs\Python\Python311\Lib\http\client.py", line 1282, in request
    self._send_request(method, url, body, headers, encode_chunked)
  File "C:\Users\zjq13\AppData\Local\Programs\Python\Python311\Lib\http\client.py", line 1328, in _send_request
    self.endheaders(body, encode_chunked=encode_chunked)
  File "C:\Users\zjq13\AppData\Local\Programs\Python\Python311\Lib\http\client.py", line 1277, in endheaders
    self._send_output(message_body, encode_chunked=encode_chunked)
  File "C:\Users\zjq13\AppData\Local\Programs\Python\Python311\Lib\http\client.py", line 1037, in _send_output
    self.send(msg)
  File "C:\Users\zjq13\AppData\Local\Programs\Python\Python311\Lib\http\client.py", line 975, in send
    self.connect()
  File "C:\Users\zjq13\AppData\Local\Programs\Python\Python311\Lib\site-packages\urllib3\connection.py", line 205, in connect
    conn = self._new_conn()
           ^^^^^^^^^^^^^^^^
  File "C:\Users\zjq13\AppData\Local\Programs\Python\Python311\Lib\site-packages\urllib3\connection.py", line 186, in _new_conn
    raise NewConnectionError(
urllib3.exceptions.NewConnectionError: <urllib3.connection.HTTPConnection object at 0x000001DC1E86EA90>: Failed to establish a new connection: [WinError 10061] 由于目标计算机积极拒绝，无法连接。

During handling of the above exception, another exception occurred:

Traceback (most recent call last):
  File "C:\Users\zjq13\AppData\Local\Programs\Python\Python311\Lib\site-packages\requests\adapters.py", line 489, in send
    resp = conn.urlopen(
           ^^^^^^^^^^^^^
  File "C:\Users\zjq13\AppData\Local\Programs\Python\Python311\Lib\site-packages\urllib3\connectionpool.py", line 787, in urlopen
    retries = retries.increment(
              ^^^^^^^^^^^^^^^^^^
  File "C:\Users\zjq13\AppData\Local\Programs\Python\Python311\Lib\site-packages\urllib3\util\retry.py", line 592, in increment
    raise MaxRetryError(_pool, url, error or ResponseError(cause))
urllib3.exceptions.MaxRetryError: HTTPConnectionPool(host='127.0.0.1', port=1111): Max retries exceeded with url: /blacklist/sync/ (Caused by NewConnectionError('<urllib3.connection.HTTPConnection object at 0x000001DC1E86EA90>: Failed to establish a new connection: [WinError 10061] 由于目标计算机积极拒绝，无法连接。'))

During handling of the above exception, another exception occurred:

Traceback (most recent call last):
  File "E:\zjq13\Documents\GitHub\bread_dog_bot\blacklist_server\main.py", line 153, in sync_all
    r = get(f"http://{s}/blacklist/sync/")
        ^^^^^^^^^^^^^^^^^^^^^^^^^^^^^^^^^^
  File "C:\Users\zjq13\AppData\Local\Programs\Python\Python311\Lib\site-packages\requests\api.py", line 73, in get
    return request("get", url, params=params, **kwargs)
           ^^^^^^^^^^^^^^^^^^^^^^^^^^^^^^^^^^^^^^^^^^^^
  File "C:\Users\zjq13\AppData\Local\Programs\Python\Python311\Lib\site-packages\requests\api.py", line 59, in request
    return session.request(method=method, url=url, **kwargs)
           ^^^^^^^^^^^^^^^^^^^^^^^^^^^^^^^^^^^^^^^^^^^^^^^^^
  File "C:\Users\zjq13\AppData\Local\Programs\Python\Python311\Lib\site-packages\requests\sessions.py", line 587, in request
    resp = self.send(prep, **send_kwargs)
           ^^^^^^^^^^^^^^^^^^^^^^^^^^^^^^
  File "C:\Users\zjq13\AppData\Local\Programs\Python\Python311\Lib\site-packages\requests\sessions.py", line 701, in send
    r = adapter.send(request, **kwargs)
        ^^^^^^^^^^^^^^^^^^^^^^^^^^^^^^^
  File "C:\Users\zjq13\AppData\Local\Programs\Python\Python311\Lib\site-packages\requests\adapters.py", line 565, in send
    raise ConnectionError(e, request=request)
requests.exceptions.ConnectionError: HTTPConnectionPool(host='127.0.0.1', port=1111): Max retries exceeded with url: /blacklist/sync/ (Caused by NewConnectionError('<urllib3.connection.HTTPConnection object at 0x000001DC1E86EA90>: Failed to establish a new connection: [WinError 10061] 由于目标计算机积极拒绝，无法连接。'))
[12/09/22 10:31:24] 向所有服务器发送同步云黑请求...
[12/09/22 10:31:24] 向服务器127.0.0.1:1111发送请求...
[12/09/22 10:31:26] 服务器连接出错:HTTPConnectionPool(host='127.0.0.1', port=1111): Max retries exceeded with url: /blacklist/sync/ (Caused by NewConnectionError('<urllib3.connection.HTTPConnection object at 0x000001DC1E87CA10>: Failed to establish a new connection: [WinError 10061] 由于目标计算机积极拒绝，无法连接。'))
Traceback (most recent call last):
  File "C:\Users\zjq13\AppData\Local\Programs\Python\Python311\Lib\site-packages\urllib3\connection.py", line 174, in _new_conn
    conn = connection.create_connection(
           ^^^^^^^^^^^^^^^^^^^^^^^^^^^^^
  File "C:\Users\zjq13\AppData\Local\Programs\Python\Python311\Lib\site-packages\urllib3\util\connection.py", line 95, in create_connection
    raise err
  File "C:\Users\zjq13\AppData\Local\Programs\Python\Python311\Lib\site-packages\urllib3\util\connection.py", line 85, in create_connection
    sock.connect(sa)
ConnectionRefusedError: [WinError 10061] 由于目标计算机积极拒绝，无法连接。

During handling of the above exception, another exception occurred:

Traceback (most recent call last):
  File "C:\Users\zjq13\AppData\Local\Programs\Python\Python311\Lib\site-packages\urllib3\connectionpool.py", line 703, in urlopen
    httplib_response = self._make_request(
                       ^^^^^^^^^^^^^^^^^^^
  File "C:\Users\zjq13\AppData\Local\Programs\Python\Python311\Lib\site-packages\urllib3\connectionpool.py", line 398, in _make_request
    conn.request(method, url, **httplib_request_kw)
  File "C:\Users\zjq13\AppData\Local\Programs\Python\Python311\Lib\site-packages\urllib3\connection.py", line 239, in request
    super(HTTPConnection, self).request(method, url, body=body, headers=headers)
  File "C:\Users\zjq13\AppData\Local\Programs\Python\Python311\Lib\http\client.py", line 1282, in request
    self._send_request(method, url, body, headers, encode_chunked)
  File "C:\Users\zjq13\AppData\Local\Programs\Python\Python311\Lib\http\client.py", line 1328, in _send_request
    self.endheaders(body, encode_chunked=encode_chunked)
  File "C:\Users\zjq13\AppData\Local\Programs\Python\Python311\Lib\http\client.py", line 1277, in endheaders
    self._send_output(message_body, encode_chunked=encode_chunked)
  File "C:\Users\zjq13\AppData\Local\Programs\Python\Python311\Lib\http\client.py", line 1037, in _send_output
    self.send(msg)
  File "C:\Users\zjq13\AppData\Local\Programs\Python\Python311\Lib\http\client.py", line 975, in send
    self.connect()
  File "C:\Users\zjq13\AppData\Local\Programs\Python\Python311\Lib\site-packages\urllib3\connection.py", line 205, in connect
    conn = self._new_conn()
           ^^^^^^^^^^^^^^^^
  File "C:\Users\zjq13\AppData\Local\Programs\Python\Python311\Lib\site-packages\urllib3\connection.py", line 186, in _new_conn
    raise NewConnectionError(
urllib3.exceptions.NewConnectionError: <urllib3.connection.HTTPConnection object at 0x000001DC1E87CA10>: Failed to establish a new connection: [WinError 10061] 由于目标计算机积极拒绝，无法连接。

During handling of the above exception, another exception occurred:

Traceback (most recent call last):
  File "C:\Users\zjq13\AppData\Local\Programs\Python\Python311\Lib\site-packages\requests\adapters.py", line 489, in send
    resp = conn.urlopen(
           ^^^^^^^^^^^^^
  File "C:\Users\zjq13\AppData\Local\Programs\Python\Python311\Lib\site-packages\urllib3\connectionpool.py", line 787, in urlopen
    retries = retries.increment(
              ^^^^^^^^^^^^^^^^^^
  File "C:\Users\zjq13\AppData\Local\Programs\Python\Python311\Lib\site-packages\urllib3\util\retry.py", line 592, in increment
    raise MaxRetryError(_pool, url, error or ResponseError(cause))
urllib3.exceptions.MaxRetryError: HTTPConnectionPool(host='127.0.0.1', port=1111): Max retries exceeded with url: /blacklist/sync/ (Caused by NewConnectionError('<urllib3.connection.HTTPConnection object at 0x000001DC1E87CA10>: Failed to establish a new connection: [WinError 10061] 由于目标计算机积极拒绝，无法连接。'))

During handling of the above exception, another exception occurred:

Traceback (most recent call last):
  File "E:\zjq13\Documents\GitHub\bread_dog_bot\blacklist_server\main.py", line 153, in sync_all
    r = get(f"http://{s}/blacklist/sync/")
        ^^^^^^^^^^^^^^^^^^^^^^^^^^^^^^^^^^
  File "C:\Users\zjq13\AppData\Local\Programs\Python\Python311\Lib\site-packages\requests\api.py", line 73, in get
    return request("get", url, params=params, **kwargs)
           ^^^^^^^^^^^^^^^^^^^^^^^^^^^^^^^^^^^^^^^^^^^^
  File "C:\Users\zjq13\AppData\Local\Programs\Python\Python311\Lib\site-packages\requests\api.py", line 59, in request
    return session.request(method=method, url=url, **kwargs)
           ^^^^^^^^^^^^^^^^^^^^^^^^^^^^^^^^^^^^^^^^^^^^^^^^^
  File "C:\Users\zjq13\AppData\Local\Programs\Python\Python311\Lib\site-packages\requests\sessions.py", line 587, in request
    resp = self.send(prep, **send_kwargs)
           ^^^^^^^^^^^^^^^^^^^^^^^^^^^^^^
  File "C:\Users\zjq13\AppData\Local\Programs\Python\Python311\Lib\site-packages\requests\sessions.py", line 701, in send
    r = adapter.send(request, **kwargs)
        ^^^^^^^^^^^^^^^^^^^^^^^^^^^^^^^
  File "C:\Users\zjq13\AppData\Local\Programs\Python\Python311\Lib\site-packages\requests\adapters.py", line 565, in send
    raise ConnectionError(e, request=request)
requests.exceptions.ConnectionError: HTTPConnectionPool(host='127.0.0.1', port=1111): Max retries exceeded with url: /blacklist/sync/ (Caused by NewConnectionError('<urllib3.connection.HTTPConnection object at 0x000001DC1E87CA10>: Failed to establish a new connection: [WinError 10061] 由于目标计算机积极拒绝，无法连接。'))
[12/09/22 10:31:36] 向所有服务器发送同步云黑请求...
[12/09/22 10:31:36] 向服务器127.0.0.1:1111发送请求...
[12/09/22 10:31:38] 服务器连接出错:HTTPConnectionPool(host='127.0.0.1', port=1111): Max retries exceeded with url: /blacklist/sync/ (Caused by NewConnectionError('<urllib3.connection.HTTPConnection object at 0x000001DC1E87EC50>: Failed to establish a new connection: [WinError 10061] 由于目标计算机积极拒绝，无法连接。'))
Traceback (most recent call last):
  File "C:\Users\zjq13\AppData\Local\Programs\Python\Python311\Lib\site-packages\urllib3\connection.py", line 174, in _new_conn
    conn = connection.create_connection(
           ^^^^^^^^^^^^^^^^^^^^^^^^^^^^^
  File "C:\Users\zjq13\AppData\Local\Programs\Python\Python311\Lib\site-packages\urllib3\util\connection.py", line 95, in create_connection
    raise err
  File "C:\Users\zjq13\AppData\Local\Programs\Python\Python311\Lib\site-packages\urllib3\util\connection.py", line 85, in create_connection
    sock.connect(sa)
ConnectionRefusedError: [WinError 10061] 由于目标计算机积极拒绝，无法连接。

During handling of the above exception, another exception occurred:

Traceback (most recent call last):
  File "C:\Users\zjq13\AppData\Local\Programs\Python\Python311\Lib\site-packages\urllib3\connectionpool.py", line 703, in urlopen
    httplib_response = self._make_request(
                       ^^^^^^^^^^^^^^^^^^^
  File "C:\Users\zjq13\AppData\Local\Programs\Python\Python311\Lib\site-packages\urllib3\connectionpool.py", line 398, in _make_request
    conn.request(method, url, **httplib_request_kw)
  File "C:\Users\zjq13\AppData\Local\Programs\Python\Python311\Lib\site-packages\urllib3\connection.py", line 239, in request
    super(HTTPConnection, self).request(method, url, body=body, headers=headers)
  File "C:\Users\zjq13\AppData\Local\Programs\Python\Python311\Lib\http\client.py", line 1282, in request
    self._send_request(method, url, body, headers, encode_chunked)
  File "C:\Users\zjq13\AppData\Local\Programs\Python\Python311\Lib\http\client.py", line 1328, in _send_request
    self.endheaders(body, encode_chunked=encode_chunked)
  File "C:\Users\zjq13\AppData\Local\Programs\Python\Python311\Lib\http\client.py", line 1277, in endheaders
    self._send_output(message_body, encode_chunked=encode_chunked)
  File "C:\Users\zjq13\AppData\Local\Programs\Python\Python311\Lib\http\client.py", line 1037, in _send_output
    self.send(msg)
  File "C:\Users\zjq13\AppData\Local\Programs\Python\Python311\Lib\http\client.py", line 975, in send
    self.connect()
  File "C:\Users\zjq13\AppData\Local\Programs\Python\Python311\Lib\site-packages\urllib3\connection.py", line 205, in connect
    conn = self._new_conn()
           ^^^^^^^^^^^^^^^^
  File "C:\Users\zjq13\AppData\Local\Programs\Python\Python311\Lib\site-packages\urllib3\connection.py", line 186, in _new_conn
    raise NewConnectionError(
urllib3.exceptions.NewConnectionError: <urllib3.connection.HTTPConnection object at 0x000001DC1E87EC50>: Failed to establish a new connection: [WinError 10061] 由于目标计算机积极拒绝，无法连接。

During handling of the above exception, another exception occurred:

Traceback (most recent call last):
  File "C:\Users\zjq13\AppData\Local\Programs\Python\Python311\Lib\site-packages\requests\adapters.py", line 489, in send
    resp = conn.urlopen(
           ^^^^^^^^^^^^^
  File "C:\Users\zjq13\AppData\Local\Programs\Python\Python311\Lib\site-packages\urllib3\connectionpool.py", line 787, in urlopen
    retries = retries.increment(
              ^^^^^^^^^^^^^^^^^^
  File "C:\Users\zjq13\AppData\Local\Programs\Python\Python311\Lib\site-packages\urllib3\util\retry.py", line 592, in increment
    raise MaxRetryError(_pool, url, error or ResponseError(cause))
urllib3.exceptions.MaxRetryError: HTTPConnectionPool(host='127.0.0.1', port=1111): Max retries exceeded with url: /blacklist/sync/ (Caused by NewConnectionError('<urllib3.connection.HTTPConnection object at 0x000001DC1E87EC50>: Failed to establish a new connection: [WinError 10061] 由于目标计算机积极拒绝，无法连接。'))

During handling of the above exception, another exception occurred:

Traceback (most recent call last):
  File "E:\zjq13\Documents\GitHub\bread_dog_bot\blacklist_server\main.py", line 153, in sync_all
    r = get(f"http://{s}/blacklist/sync/")
        ^^^^^^^^^^^^^^^^^^^^^^^^^^^^^^^^^^
  File "C:\Users\zjq13\AppData\Local\Programs\Python\Python311\Lib\site-packages\requests\api.py", line 73, in get
    return request("get", url, params=params, **kwargs)
           ^^^^^^^^^^^^^^^^^^^^^^^^^^^^^^^^^^^^^^^^^^^^
  File "C:\Users\zjq13\AppData\Local\Programs\Python\Python311\Lib\site-packages\requests\api.py", line 59, in request
    return session.request(method=method, url=url, **kwargs)
           ^^^^^^^^^^^^^^^^^^^^^^^^^^^^^^^^^^^^^^^^^^^^^^^^^
  File "C:\Users\zjq13\AppData\Local\Programs\Python\Python311\Lib\site-packages\requests\sessions.py", line 587, in request
    resp = self.send(prep, **send_kwargs)
           ^^^^^^^^^^^^^^^^^^^^^^^^^^^^^^
  File "C:\Users\zjq13\AppData\Local\Programs\Python\Python311\Lib\site-packages\requests\sessions.py", line 701, in send
    r = adapter.send(request, **kwargs)
        ^^^^^^^^^^^^^^^^^^^^^^^^^^^^^^^
  File "C:\Users\zjq13\AppData\Local\Programs\Python\Python311\Lib\site-packages\requests\adapters.py", line 565, in send
    raise ConnectionError(e, request=request)
requests.exceptions.ConnectionError: HTTPConnectionPool(host='127.0.0.1', port=1111): Max retries exceeded with url: /blacklist/sync/ (Caused by NewConnectionError('<urllib3.connection.HTTPConnection object at 0x000001DC1E87EC50>: Failed to establish a new connection: [WinError 10061] 由于目标计算机积极拒绝，无法连接。'))
[12/09/22 10:31:48] 向所有服务器发送同步云黑请求...
[12/09/22 10:31:48] 向服务器127.0.0.1:1111发送请求...
[12/09/22 10:31:50] 服务器连接出错:HTTPConnectionPool(host='127.0.0.1', port=1111): Max retries exceeded with url: /blacklist/sync/ (Caused by NewConnectionError('<urllib3.connection.HTTPConnection object at 0x000001DC1E857610>: Failed to establish a new connection: [WinError 10061] 由于目标计算机积极拒绝，无法连接。'))
Traceback (most recent call last):
  File "C:\Users\zjq13\AppData\Local\Programs\Python\Python311\Lib\site-packages\urllib3\connection.py", line 174, in _new_conn
    conn = connection.create_connection(
           ^^^^^^^^^^^^^^^^^^^^^^^^^^^^^
  File "C:\Users\zjq13\AppData\Local\Programs\Python\Python311\Lib\site-packages\urllib3\util\connection.py", line 95, in create_connection
    raise err
  File "C:\Users\zjq13\AppData\Local\Programs\Python\Python311\Lib\site-packages\urllib3\util\connection.py", line 85, in create_connection
    sock.connect(sa)
ConnectionRefusedError: [WinError 10061] 由于目标计算机积极拒绝，无法连接。

During handling of the above exception, another exception occurred:

Traceback (most recent call last):
  File "C:\Users\zjq13\AppData\Local\Programs\Python\Python311\Lib\site-packages\urllib3\connectionpool.py", line 703, in urlopen
    httplib_response = self._make_request(
                       ^^^^^^^^^^^^^^^^^^^
  File "C:\Users\zjq13\AppData\Local\Programs\Python\Python311\Lib\site-packages\urllib3\connectionpool.py", line 398, in _make_request
    conn.request(method, url, **httplib_request_kw)
  File "C:\Users\zjq13\AppData\Local\Programs\Python\Python311\Lib\site-packages\urllib3\connection.py", line 239, in request
    super(HTTPConnection, self).request(method, url, body=body, headers=headers)
  File "C:\Users\zjq13\AppData\Local\Programs\Python\Python311\Lib\http\client.py", line 1282, in request
    self._send_request(method, url, body, headers, encode_chunked)
  File "C:\Users\zjq13\AppData\Local\Programs\Python\Python311\Lib\http\client.py", line 1328, in _send_request
    self.endheaders(body, encode_chunked=encode_chunked)
  File "C:\Users\zjq13\AppData\Local\Programs\Python\Python311\Lib\http\client.py", line 1277, in endheaders
    self._send_output(message_body, encode_chunked=encode_chunked)
  File "C:\Users\zjq13\AppData\Local\Programs\Python\Python311\Lib\http\client.py", line 1037, in _send_output
    self.send(msg)
  File "C:\Users\zjq13\AppData\Local\Programs\Python\Python311\Lib\http\client.py", line 975, in send
    self.connect()
  File "C:\Users\zjq13\AppData\Local\Programs\Python\Python311\Lib\site-packages\urllib3\connection.py", line 205, in connect
    conn = self._new_conn()
           ^^^^^^^^^^^^^^^^
  File "C:\Users\zjq13\AppData\Local\Programs\Python\Python311\Lib\site-packages\urllib3\connection.py", line 186, in _new_conn
    raise NewConnectionError(
urllib3.exceptions.NewConnectionError: <urllib3.connection.HTTPConnection object at 0x000001DC1E857610>: Failed to establish a new connection: [WinError 10061] 由于目标计算机积极拒绝，无法连接。

During handling of the above exception, another exception occurred:

Traceback (most recent call last):
  File "C:\Users\zjq13\AppData\Local\Programs\Python\Python311\Lib\site-packages\requests\adapters.py", line 489, in send
    resp = conn.urlopen(
           ^^^^^^^^^^^^^
  File "C:\Users\zjq13\AppData\Local\Programs\Python\Python311\Lib\site-packages\urllib3\connectionpool.py", line 787, in urlopen
    retries = retries.increment(
              ^^^^^^^^^^^^^^^^^^
  File "C:\Users\zjq13\AppData\Local\Programs\Python\Python311\Lib\site-packages\urllib3\util\retry.py", line 592, in increment
    raise MaxRetryError(_pool, url, error or ResponseError(cause))
urllib3.exceptions.MaxRetryError: HTTPConnectionPool(host='127.0.0.1', port=1111): Max retries exceeded with url: /blacklist/sync/ (Caused by NewConnectionError('<urllib3.connection.HTTPConnection object at 0x000001DC1E857610>: Failed to establish a new connection: [WinError 10061] 由于目标计算机积极拒绝，无法连接。'))

During handling of the above exception, another exception occurred:

Traceback (most recent call last):
  File "E:\zjq13\Documents\GitHub\bread_dog_bot\blacklist_server\main.py", line 153, in sync_all
    r = get(f"http://{s}/blacklist/sync/")
        ^^^^^^^^^^^^^^^^^^^^^^^^^^^^^^^^^^
  File "C:\Users\zjq13\AppData\Local\Programs\Python\Python311\Lib\site-packages\requests\api.py", line 73, in get
    return request("get", url, params=params, **kwargs)
           ^^^^^^^^^^^^^^^^^^^^^^^^^^^^^^^^^^^^^^^^^^^^
  File "C:\Users\zjq13\AppData\Local\Programs\Python\Python311\Lib\site-packages\requests\api.py", line 59, in request
    return session.request(method=method, url=url, **kwargs)
           ^^^^^^^^^^^^^^^^^^^^^^^^^^^^^^^^^^^^^^^^^^^^^^^^^
  File "C:\Users\zjq13\AppData\Local\Programs\Python\Python311\Lib\site-packages\requests\sessions.py", line 587, in request
    resp = self.send(prep, **send_kwargs)
           ^^^^^^^^^^^^^^^^^^^^^^^^^^^^^^
  File "C:\Users\zjq13\AppData\Local\Programs\Python\Python311\Lib\site-packages\requests\sessions.py", line 701, in send
    r = adapter.send(request, **kwargs)
        ^^^^^^^^^^^^^^^^^^^^^^^^^^^^^^^
  File "C:\Users\zjq13\AppData\Local\Programs\Python\Python311\Lib\site-packages\requests\adapters.py", line 565, in send
    raise ConnectionError(e, request=request)
requests.exceptions.ConnectionError: HTTPConnectionPool(host='127.0.0.1', port=1111): Max retries exceeded with url: /blacklist/sync/ (Caused by NewConnectionError('<urllib3.connection.HTTPConnection object at 0x000001DC1E857610>: Failed to establish a new connection: [WinError 10061] 由于目标计算机积极拒绝，无法连接。'))
[12/09/22 10:32:01] 向所有服务器发送同步云黑请求...
[12/09/22 10:32:01] 向服务器127.0.0.1:1111发送请求...
[12/09/22 10:32:03] 服务器连接出错:HTTPConnectionPool(host='127.0.0.1', port=1111): Max retries exceeded with url: /blacklist/sync/ (Caused by NewConnectionError('<urllib3.connection.HTTPConnection object at 0x000001DC1E857090>: Failed to establish a new connection: [WinError 10061] 由于目标计算机积极拒绝，无法连接。'))
Traceback (most recent call last):
  File "C:\Users\zjq13\AppData\Local\Programs\Python\Python311\Lib\site-packages\urllib3\connection.py", line 174, in _new_conn
    conn = connection.create_connection(
           ^^^^^^^^^^^^^^^^^^^^^^^^^^^^^
  File "C:\Users\zjq13\AppData\Local\Programs\Python\Python311\Lib\site-packages\urllib3\util\connection.py", line 95, in create_connection
    raise err
  File "C:\Users\zjq13\AppData\Local\Programs\Python\Python311\Lib\site-packages\urllib3\util\connection.py", line 85, in create_connection
    sock.connect(sa)
ConnectionRefusedError: [WinError 10061] 由于目标计算机积极拒绝，无法连接。

During handling of the above exception, another exception occurred:

Traceback (most recent call last):
  File "C:\Users\zjq13\AppData\Local\Programs\Python\Python311\Lib\site-packages\urllib3\connectionpool.py", line 703, in urlopen
    httplib_response = self._make_request(
                       ^^^^^^^^^^^^^^^^^^^
  File "C:\Users\zjq13\AppData\Local\Programs\Python\Python311\Lib\site-packages\urllib3\connectionpool.py", line 398, in _make_request
    conn.request(method, url, **httplib_request_kw)
  File "C:\Users\zjq13\AppData\Local\Programs\Python\Python311\Lib\site-packages\urllib3\connection.py", line 239, in request
    super(HTTPConnection, self).request(method, url, body=body, headers=headers)
  File "C:\Users\zjq13\AppData\Local\Programs\Python\Python311\Lib\http\client.py", line 1282, in request
    self._send_request(method, url, body, headers, encode_chunked)
  File "C:\Users\zjq13\AppData\Local\Programs\Python\Python311\Lib\http\client.py", line 1328, in _send_request
    self.endheaders(body, encode_chunked=encode_chunked)
  File "C:\Users\zjq13\AppData\Local\Programs\Python\Python311\Lib\http\client.py", line 1277, in endheaders
    self._send_output(message_body, encode_chunked=encode_chunked)
  File "C:\Users\zjq13\AppData\Local\Programs\Python\Python311\Lib\http\client.py", line 1037, in _send_output
    self.send(msg)
  File "C:\Users\zjq13\AppData\Local\Programs\Python\Python311\Lib\http\client.py", line 975, in send
    self.connect()
  File "C:\Users\zjq13\AppData\Local\Programs\Python\Python311\Lib\site-packages\urllib3\connection.py", line 205, in connect
    conn = self._new_conn()
           ^^^^^^^^^^^^^^^^
  File "C:\Users\zjq13\AppData\Local\Programs\Python\Python311\Lib\site-packages\urllib3\connection.py", line 186, in _new_conn
    raise NewConnectionError(
urllib3.exceptions.NewConnectionError: <urllib3.connection.HTTPConnection object at 0x000001DC1E857090>: Failed to establish a new connection: [WinError 10061] 由于目标计算机积极拒绝，无法连接。

During handling of the above exception, another exception occurred:

Traceback (most recent call last):
  File "C:\Users\zjq13\AppData\Local\Programs\Python\Python311\Lib\site-packages\requests\adapters.py", line 489, in send
    resp = conn.urlopen(
           ^^^^^^^^^^^^^
  File "C:\Users\zjq13\AppData\Local\Programs\Python\Python311\Lib\site-packages\urllib3\connectionpool.py", line 787, in urlopen
    retries = retries.increment(
              ^^^^^^^^^^^^^^^^^^
  File "C:\Users\zjq13\AppData\Local\Programs\Python\Python311\Lib\site-packages\urllib3\util\retry.py", line 592, in increment
    raise MaxRetryError(_pool, url, error or ResponseError(cause))
urllib3.exceptions.MaxRetryError: HTTPConnectionPool(host='127.0.0.1', port=1111): Max retries exceeded with url: /blacklist/sync/ (Caused by NewConnectionError('<urllib3.connection.HTTPConnection object at 0x000001DC1E857090>: Failed to establish a new connection: [WinError 10061] 由于目标计算机积极拒绝，无法连接。'))

During handling of the above exception, another exception occurred:

Traceback (most recent call last):
  File "E:\zjq13\Documents\GitHub\bread_dog_bot\blacklist_server\main.py", line 153, in sync_all
    r = get(f"http://{s}/blacklist/sync/")
        ^^^^^^^^^^^^^^^^^^^^^^^^^^^^^^^^^^
  File "C:\Users\zjq13\AppData\Local\Programs\Python\Python311\Lib\site-packages\requests\api.py", line 73, in get
    return request("get", url, params=params, **kwargs)
           ^^^^^^^^^^^^^^^^^^^^^^^^^^^^^^^^^^^^^^^^^^^^
  File "C:\Users\zjq13\AppData\Local\Programs\Python\Python311\Lib\site-packages\requests\api.py", line 59, in request
    return session.request(method=method, url=url, **kwargs)
           ^^^^^^^^^^^^^^^^^^^^^^^^^^^^^^^^^^^^^^^^^^^^^^^^^
  File "C:\Users\zjq13\AppData\Local\Programs\Python\Python311\Lib\site-packages\requests\sessions.py", line 587, in request
    resp = self.send(prep, **send_kwargs)
           ^^^^^^^^^^^^^^^^^^^^^^^^^^^^^^
  File "C:\Users\zjq13\AppData\Local\Programs\Python\Python311\Lib\site-packages\requests\sessions.py", line 701, in send
    r = adapter.send(request, **kwargs)
        ^^^^^^^^^^^^^^^^^^^^^^^^^^^^^^^
  File "C:\Users\zjq13\AppData\Local\Programs\Python\Python311\Lib\site-packages\requests\adapters.py", line 565, in send
    raise ConnectionError(e, request=request)
requests.exceptions.ConnectionError: HTTPConnectionPool(host='127.0.0.1', port=1111): Max retries exceeded with url: /blacklist/sync/ (Caused by NewConnectionError('<urllib3.connection.HTTPConnection object at 0x000001DC1E857090>: Failed to establish a new connection: [WinError 10061] 由于目标计算机积极拒绝，无法连接。'))
[12/09/22 10:32:13] 向所有服务器发送同步云黑请求...
[12/09/22 10:32:13] 向服务器127.0.0.1:1111发送请求...
[12/09/22 10:32:15] 服务器连接出错:HTTPConnectionPool(host='127.0.0.1', port=1111): Max retries exceeded with url: /blacklist/sync/ (Caused by NewConnectionError('<urllib3.connection.HTTPConnection object at 0x000001DC1E86EA50>: Failed to establish a new connection: [WinError 10061] 由于目标计算机积极拒绝，无法连接。'))
Traceback (most recent call last):
  File "C:\Users\zjq13\AppData\Local\Programs\Python\Python311\Lib\site-packages\urllib3\connection.py", line 174, in _new_conn
    conn = connection.create_connection(
           ^^^^^^^^^^^^^^^^^^^^^^^^^^^^^
  File "C:\Users\zjq13\AppData\Local\Programs\Python\Python311\Lib\site-packages\urllib3\util\connection.py", line 95, in create_connection
    raise err
  File "C:\Users\zjq13\AppData\Local\Programs\Python\Python311\Lib\site-packages\urllib3\util\connection.py", line 85, in create_connection
    sock.connect(sa)
ConnectionRefusedError: [WinError 10061] 由于目标计算机积极拒绝，无法连接。

During handling of the above exception, another exception occurred:

Traceback (most recent call last):
  File "C:\Users\zjq13\AppData\Local\Programs\Python\Python311\Lib\site-packages\urllib3\connectionpool.py", line 703, in urlopen
    httplib_response = self._make_request(
                       ^^^^^^^^^^^^^^^^^^^
  File "C:\Users\zjq13\AppData\Local\Programs\Python\Python311\Lib\site-packages\urllib3\connectionpool.py", line 398, in _make_request
    conn.request(method, url, **httplib_request_kw)
  File "C:\Users\zjq13\AppData\Local\Programs\Python\Python311\Lib\site-packages\urllib3\connection.py", line 239, in request
    super(HTTPConnection, self).request(method, url, body=body, headers=headers)
  File "C:\Users\zjq13\AppData\Local\Programs\Python\Python311\Lib\http\client.py", line 1282, in request
    self._send_request(method, url, body, headers, encode_chunked)
  File "C:\Users\zjq13\AppData\Local\Programs\Python\Python311\Lib\http\client.py", line 1328, in _send_request
    self.endheaders(body, encode_chunked=encode_chunked)
  File "C:\Users\zjq13\AppData\Local\Programs\Python\Python311\Lib\http\client.py", line 1277, in endheaders
    self._send_output(message_body, encode_chunked=encode_chunked)
  File "C:\Users\zjq13\AppData\Local\Programs\Python\Python311\Lib\http\client.py", line 1037, in _send_output
    self.send(msg)
  File "C:\Users\zjq13\AppData\Local\Programs\Python\Python311\Lib\http\client.py", line 975, in send
    self.connect()
  File "C:\Users\zjq13\AppData\Local\Programs\Python\Python311\Lib\site-packages\urllib3\connection.py", line 205, in connect
    conn = self._new_conn()
           ^^^^^^^^^^^^^^^^
  File "C:\Users\zjq13\AppData\Local\Programs\Python\Python311\Lib\site-packages\urllib3\connection.py", line 186, in _new_conn
    raise NewConnectionError(
urllib3.exceptions.NewConnectionError: <urllib3.connection.HTTPConnection object at 0x000001DC1E86EA50>: Failed to establish a new connection: [WinError 10061] 由于目标计算机积极拒绝，无法连接。

During handling of the above exception, another exception occurred:

Traceback (most recent call last):
  File "C:\Users\zjq13\AppData\Local\Programs\Python\Python311\Lib\site-packages\requests\adapters.py", line 489, in send
    resp = conn.urlopen(
           ^^^^^^^^^^^^^
  File "C:\Users\zjq13\AppData\Local\Programs\Python\Python311\Lib\site-packages\urllib3\connectionpool.py", line 787, in urlopen
    retries = retries.increment(
              ^^^^^^^^^^^^^^^^^^
  File "C:\Users\zjq13\AppData\Local\Programs\Python\Python311\Lib\site-packages\urllib3\util\retry.py", line 592, in increment
    raise MaxRetryError(_pool, url, error or ResponseError(cause))
urllib3.exceptions.MaxRetryError: HTTPConnectionPool(host='127.0.0.1', port=1111): Max retries exceeded with url: /blacklist/sync/ (Caused by NewConnectionError('<urllib3.connection.HTTPConnection object at 0x000001DC1E86EA50>: Failed to establish a new connection: [WinError 10061] 由于目标计算机积极拒绝，无法连接。'))

During handling of the above exception, another exception occurred:

Traceback (most recent call last):
  File "E:\zjq13\Documents\GitHub\bread_dog_bot\blacklist_server\main.py", line 153, in sync_all
    r = get(f"http://{s}/blacklist/sync/")
        ^^^^^^^^^^^^^^^^^^^^^^^^^^^^^^^^^^
  File "C:\Users\zjq13\AppData\Local\Programs\Python\Python311\Lib\site-packages\requests\api.py", line 73, in get
    return request("get", url, params=params, **kwargs)
           ^^^^^^^^^^^^^^^^^^^^^^^^^^^^^^^^^^^^^^^^^^^^
  File "C:\Users\zjq13\AppData\Local\Programs\Python\Python311\Lib\site-packages\requests\api.py", line 59, in request
    return session.request(method=method, url=url, **kwargs)
           ^^^^^^^^^^^^^^^^^^^^^^^^^^^^^^^^^^^^^^^^^^^^^^^^^
  File "C:\Users\zjq13\AppData\Local\Programs\Python\Python311\Lib\site-packages\requests\sessions.py", line 587, in request
    resp = self.send(prep, **send_kwargs)
           ^^^^^^^^^^^^^^^^^^^^^^^^^^^^^^
  File "C:\Users\zjq13\AppData\Local\Programs\Python\Python311\Lib\site-packages\requests\sessions.py", line 701, in send
    r = adapter.send(request, **kwargs)
        ^^^^^^^^^^^^^^^^^^^^^^^^^^^^^^^
  File "C:\Users\zjq13\AppData\Local\Programs\Python\Python311\Lib\site-packages\requests\adapters.py", line 565, in send
    raise ConnectionError(e, request=request)
requests.exceptions.ConnectionError: HTTPConnectionPool(host='127.0.0.1', port=1111): Max retries exceeded with url: /blacklist/sync/ (Caused by NewConnectionError('<urllib3.connection.HTTPConnection object at 0x000001DC1E86EA50>: Failed to establish a new connection: [WinError 10061] 由于目标计算机积极拒绝，无法连接。'))
[12/09/22 10:32:25] 向所有服务器发送同步云黑请求...
[12/09/22 10:32:25] 向服务器127.0.0.1:1111发送请求...
[12/09/22 10:32:27] 服务器连接出错:HTTPConnectionPool(host='127.0.0.1', port=1111): Max retries exceeded with url: /blacklist/sync/ (Caused by NewConnectionError('<urllib3.connection.HTTPConnection object at 0x000001DC1E860610>: Failed to establish a new connection: [WinError 10061] 由于目标计算机积极拒绝，无法连接。'))
Traceback (most recent call last):
  File "C:\Users\zjq13\AppData\Local\Programs\Python\Python311\Lib\site-packages\urllib3\connection.py", line 174, in _new_conn
    conn = connection.create_connection(
           ^^^^^^^^^^^^^^^^^^^^^^^^^^^^^
  File "C:\Users\zjq13\AppData\Local\Programs\Python\Python311\Lib\site-packages\urllib3\util\connection.py", line 95, in create_connection
    raise err
  File "C:\Users\zjq13\AppData\Local\Programs\Python\Python311\Lib\site-packages\urllib3\util\connection.py", line 85, in create_connection
    sock.connect(sa)
ConnectionRefusedError: [WinError 10061] 由于目标计算机积极拒绝，无法连接。

During handling of the above exception, another exception occurred:

Traceback (most recent call last):
  File "C:\Users\zjq13\AppData\Local\Programs\Python\Python311\Lib\site-packages\urllib3\connectionpool.py", line 703, in urlopen
    httplib_response = self._make_request(
                       ^^^^^^^^^^^^^^^^^^^
  File "C:\Users\zjq13\AppData\Local\Programs\Python\Python311\Lib\site-packages\urllib3\connectionpool.py", line 398, in _make_request
    conn.request(method, url, **httplib_request_kw)
  File "C:\Users\zjq13\AppData\Local\Programs\Python\Python311\Lib\site-packages\urllib3\connection.py", line 239, in request
    super(HTTPConnection, self).request(method, url, body=body, headers=headers)
  File "C:\Users\zjq13\AppData\Local\Programs\Python\Python311\Lib\http\client.py", line 1282, in request
    self._send_request(method, url, body, headers, encode_chunked)
  File "C:\Users\zjq13\AppData\Local\Programs\Python\Python311\Lib\http\client.py", line 1328, in _send_request
    self.endheaders(body, encode_chunked=encode_chunked)
  File "C:\Users\zjq13\AppData\Local\Programs\Python\Python311\Lib\http\client.py", line 1277, in endheaders
    self._send_output(message_body, encode_chunked=encode_chunked)
  File "C:\Users\zjq13\AppData\Local\Programs\Python\Python311\Lib\http\client.py", line 1037, in _send_output
    self.send(msg)
  File "C:\Users\zjq13\AppData\Local\Programs\Python\Python311\Lib\http\client.py", line 975, in send
    self.connect()
  File "C:\Users\zjq13\AppData\Local\Programs\Python\Python311\Lib\site-packages\urllib3\connection.py", line 205, in connect
    conn = self._new_conn()
           ^^^^^^^^^^^^^^^^
  File "C:\Users\zjq13\AppData\Local\Programs\Python\Python311\Lib\site-packages\urllib3\connection.py", line 186, in _new_conn
    raise NewConnectionError(
urllib3.exceptions.NewConnectionError: <urllib3.connection.HTTPConnection object at 0x000001DC1E860610>: Failed to establish a new connection: [WinError 10061] 由于目标计算机积极拒绝，无法连接。

During handling of the above exception, another exception occurred:

Traceback (most recent call last):
  File "C:\Users\zjq13\AppData\Local\Programs\Python\Python311\Lib\site-packages\requests\adapters.py", line 489, in send
    resp = conn.urlopen(
           ^^^^^^^^^^^^^
  File "C:\Users\zjq13\AppData\Local\Programs\Python\Python311\Lib\site-packages\urllib3\connectionpool.py", line 787, in urlopen
    retries = retries.increment(
              ^^^^^^^^^^^^^^^^^^
  File "C:\Users\zjq13\AppData\Local\Programs\Python\Python311\Lib\site-packages\urllib3\util\retry.py", line 592, in increment
    raise MaxRetryError(_pool, url, error or ResponseError(cause))
urllib3.exceptions.MaxRetryError: HTTPConnectionPool(host='127.0.0.1', port=1111): Max retries exceeded with url: /blacklist/sync/ (Caused by NewConnectionError('<urllib3.connection.HTTPConnection object at 0x000001DC1E860610>: Failed to establish a new connection: [WinError 10061] 由于目标计算机积极拒绝，无法连接。'))

During handling of the above exception, another exception occurred:

Traceback (most recent call last):
  File "E:\zjq13\Documents\GitHub\bread_dog_bot\blacklist_server\main.py", line 153, in sync_all
    r = get(f"http://{s}/blacklist/sync/")
        ^^^^^^^^^^^^^^^^^^^^^^^^^^^^^^^^^^
  File "C:\Users\zjq13\AppData\Local\Programs\Python\Python311\Lib\site-packages\requests\api.py", line 73, in get
    return request("get", url, params=params, **kwargs)
           ^^^^^^^^^^^^^^^^^^^^^^^^^^^^^^^^^^^^^^^^^^^^
  File "C:\Users\zjq13\AppData\Local\Programs\Python\Python311\Lib\site-packages\requests\api.py", line 59, in request
    return session.request(method=method, url=url, **kwargs)
           ^^^^^^^^^^^^^^^^^^^^^^^^^^^^^^^^^^^^^^^^^^^^^^^^^
  File "C:\Users\zjq13\AppData\Local\Programs\Python\Python311\Lib\site-packages\requests\sessions.py", line 587, in request
    resp = self.send(prep, **send_kwargs)
           ^^^^^^^^^^^^^^^^^^^^^^^^^^^^^^
  File "C:\Users\zjq13\AppData\Local\Programs\Python\Python311\Lib\site-packages\requests\sessions.py", line 701, in send
    r = adapter.send(request, **kwargs)
        ^^^^^^^^^^^^^^^^^^^^^^^^^^^^^^^
  File "C:\Users\zjq13\AppData\Local\Programs\Python\Python311\Lib\site-packages\requests\adapters.py", line 565, in send
    raise ConnectionError(e, request=request)
requests.exceptions.ConnectionError: HTTPConnectionPool(host='127.0.0.1', port=1111): Max retries exceeded with url: /blacklist/sync/ (Caused by NewConnectionError('<urllib3.connection.HTTPConnection object at 0x000001DC1E860610>: Failed to establish a new connection: [WinError 10061] 由于目标计算机积极拒绝，无法连接。'))
[12/09/22 10:32:37] 向所有服务器发送同步云黑请求...
[12/09/22 10:32:37] 向服务器127.0.0.1:1111发送请求...
[12/09/22 10:32:39] 服务器连接出错:HTTPConnectionPool(host='127.0.0.1', port=1111): Max retries exceeded with url: /blacklist/sync/ (Caused by NewConnectionError('<urllib3.connection.HTTPConnection object at 0x000001DC1E863550>: Failed to establish a new connection: [WinError 10061] 由于目标计算机积极拒绝，无法连接。'))
Traceback (most recent call last):
  File "C:\Users\zjq13\AppData\Local\Programs\Python\Python311\Lib\site-packages\urllib3\connection.py", line 174, in _new_conn
    conn = connection.create_connection(
           ^^^^^^^^^^^^^^^^^^^^^^^^^^^^^
  File "C:\Users\zjq13\AppData\Local\Programs\Python\Python311\Lib\site-packages\urllib3\util\connection.py", line 95, in create_connection
    raise err
  File "C:\Users\zjq13\AppData\Local\Programs\Python\Python311\Lib\site-packages\urllib3\util\connection.py", line 85, in create_connection
    sock.connect(sa)
ConnectionRefusedError: [WinError 10061] 由于目标计算机积极拒绝，无法连接。

During handling of the above exception, another exception occurred:

Traceback (most recent call last):
  File "C:\Users\zjq13\AppData\Local\Programs\Python\Python311\Lib\site-packages\urllib3\connectionpool.py", line 703, in urlopen
    httplib_response = self._make_request(
                       ^^^^^^^^^^^^^^^^^^^
  File "C:\Users\zjq13\AppData\Local\Programs\Python\Python311\Lib\site-packages\urllib3\connectionpool.py", line 398, in _make_request
    conn.request(method, url, **httplib_request_kw)
  File "C:\Users\zjq13\AppData\Local\Programs\Python\Python311\Lib\site-packages\urllib3\connection.py", line 239, in request
    super(HTTPConnection, self).request(method, url, body=body, headers=headers)
  File "C:\Users\zjq13\AppData\Local\Programs\Python\Python311\Lib\http\client.py", line 1282, in request
    self._send_request(method, url, body, headers, encode_chunked)
  File "C:\Users\zjq13\AppData\Local\Programs\Python\Python311\Lib\http\client.py", line 1328, in _send_request
    self.endheaders(body, encode_chunked=encode_chunked)
  File "C:\Users\zjq13\AppData\Local\Programs\Python\Python311\Lib\http\client.py", line 1277, in endheaders
    self._send_output(message_body, encode_chunked=encode_chunked)
  File "C:\Users\zjq13\AppData\Local\Programs\Python\Python311\Lib\http\client.py", line 1037, in _send_output
    self.send(msg)
  File "C:\Users\zjq13\AppData\Local\Programs\Python\Python311\Lib\http\client.py", line 975, in send
    self.connect()
  File "C:\Users\zjq13\AppData\Local\Programs\Python\Python311\Lib\site-packages\urllib3\connection.py", line 205, in connect
    conn = self._new_conn()
           ^^^^^^^^^^^^^^^^
  File "C:\Users\zjq13\AppData\Local\Programs\Python\Python311\Lib\site-packages\urllib3\connection.py", line 186, in _new_conn
    raise NewConnectionError(
urllib3.exceptions.NewConnectionError: <urllib3.connection.HTTPConnection object at 0x000001DC1E863550>: Failed to establish a new connection: [WinError 10061] 由于目标计算机积极拒绝，无法连接。

During handling of the above exception, another exception occurred:

Traceback (most recent call last):
  File "C:\Users\zjq13\AppData\Local\Programs\Python\Python311\Lib\site-packages\requests\adapters.py", line 489, in send
    resp = conn.urlopen(
           ^^^^^^^^^^^^^
  File "C:\Users\zjq13\AppData\Local\Programs\Python\Python311\Lib\site-packages\urllib3\connectionpool.py", line 787, in urlopen
    retries = retries.increment(
              ^^^^^^^^^^^^^^^^^^
  File "C:\Users\zjq13\AppData\Local\Programs\Python\Python311\Lib\site-packages\urllib3\util\retry.py", line 592, in increment
    raise MaxRetryError(_pool, url, error or ResponseError(cause))
urllib3.exceptions.MaxRetryError: HTTPConnectionPool(host='127.0.0.1', port=1111): Max retries exceeded with url: /blacklist/sync/ (Caused by NewConnectionError('<urllib3.connection.HTTPConnection object at 0x000001DC1E863550>: Failed to establish a new connection: [WinError 10061] 由于目标计算机积极拒绝，无法连接。'))

During handling of the above exception, another exception occurred:

Traceback (most recent call last):
  File "E:\zjq13\Documents\GitHub\bread_dog_bot\blacklist_server\main.py", line 153, in sync_all
    r = get(f"http://{s}/blacklist/sync/")
        ^^^^^^^^^^^^^^^^^^^^^^^^^^^^^^^^^^
  File "C:\Users\zjq13\AppData\Local\Programs\Python\Python311\Lib\site-packages\requests\api.py", line 73, in get
    return request("get", url, params=params, **kwargs)
           ^^^^^^^^^^^^^^^^^^^^^^^^^^^^^^^^^^^^^^^^^^^^
  File "C:\Users\zjq13\AppData\Local\Programs\Python\Python311\Lib\site-packages\requests\api.py", line 59, in request
    return session.request(method=method, url=url, **kwargs)
           ^^^^^^^^^^^^^^^^^^^^^^^^^^^^^^^^^^^^^^^^^^^^^^^^^
  File "C:\Users\zjq13\AppData\Local\Programs\Python\Python311\Lib\site-packages\requests\sessions.py", line 587, in request
    resp = self.send(prep, **send_kwargs)
           ^^^^^^^^^^^^^^^^^^^^^^^^^^^^^^
  File "C:\Users\zjq13\AppData\Local\Programs\Python\Python311\Lib\site-packages\requests\sessions.py", line 701, in send
    r = adapter.send(request, **kwargs)
        ^^^^^^^^^^^^^^^^^^^^^^^^^^^^^^^
  File "C:\Users\zjq13\AppData\Local\Programs\Python\Python311\Lib\site-packages\requests\adapters.py", line 565, in send
    raise ConnectionError(e, request=request)
requests.exceptions.ConnectionError: HTTPConnectionPool(host='127.0.0.1', port=1111): Max retries exceeded with url: /blacklist/sync/ (Caused by NewConnectionError('<urllib3.connection.HTTPConnection object at 0x000001DC1E863550>: Failed to establish a new connection: [WinError 10061] 由于目标计算机积极拒绝，无法连接。'))
[12/09/22 10:32:49] 向所有服务器发送同步云黑请求...
[12/09/22 10:32:49] 向服务器127.0.0.1:1111发送请求...
[12/09/22 10:32:49] 数据库处理出错:no such table: black_list
[12/09/22 10:32:49] 本地数据库读取错误:{'status': 200, 'data': []}
[12/09/22 10:32:53] 接收到GET请求:http://127.0.0.1:5432/
[12/09/22 10:32:53] 请求者IP为:127.0.0.1
[12/09/22 10:32:53] 接收到同步云黑数据库请求...
[12/09/22 10:32:53] 数据库处理出错:no such table: black_list
[12/09/22 10:32:53] 同步云黑数据请求失败...数据库处理时出错:no such table: black_list
[12/09/22 10:32:59] 向所有服务器发送同步云黑请求...
[12/09/22 10:32:59] 向服务器127.0.0.1:1111发送请求...
[12/09/22 10:32:59] 数据库处理出错:no such table: black_list
[12/09/22 10:32:59] 本地数据库读取错误:{'status': 200, 'data': []}
[12/09/22 10:33:09] 向所有服务器发送同步云黑请求...
[12/09/22 10:33:09] 向服务器127.0.0.1:1111发送请求...
[12/09/22 10:33:09] 数据库处理出错:no such table: black_list
[12/09/22 10:33:09] 本地数据库读取错误:{'status': 200, 'data': []}
[12/09/22 10:33:19] 向所有服务器发送同步云黑请求...
[12/09/22 10:33:19] 向服务器127.0.0.1:1111发送请求...
[12/09/22 10:33:19] 数据库处理出错:no such table: black_list
[12/09/22 10:33:19] 本地数据库读取错误:{'status': 200, 'data': []}
[12/09/22 10:33:29] 向所有服务器发送同步云黑请求...
[12/09/22 10:33:29] 向服务器127.0.0.1:1111发送请求...
[12/09/22 10:33:29] 数据库处理出错:no such table: black_list
[12/09/22 10:33:29] 本地数据库读取错误:{'status': 200, 'data': []}
[12/09/22 10:33:39] 向所有服务器发送同步云黑请求...
[12/09/22 10:33:39] 向服务器127.0.0.1:1111发送请求...
[12/09/22 10:33:39] 数据库处理出错:no such table: black_list
[12/09/22 10:33:39] 本地数据库读取错误:{'status': 200, 'data': []}
[12/09/22 10:33:50] 向所有服务器发送同步云黑请求...
[12/09/22 10:33:50] 向服务器127.0.0.1:1111发送请求...
[12/09/22 10:33:50] 数据库处理出错:no such table: black_list
[12/09/22 10:33:50] 本地数据库读取错误:{'status': 200, 'data': []}
[12/09/22 10:34:00] 向所有服务器发送同步云黑请求...
[12/09/22 10:34:00] 向服务器127.0.0.1:1111发送请求...
[12/09/22 10:34:00] 数据库处理出错:no such table: black_list
[12/09/22 10:34:00] 本地数据库读取错误:{'status': 200, 'data': []}
[12/09/22 10:34:10] 向所有服务器发送同步云黑请求...
[12/09/22 10:34:10] 向服务器127.0.0.1:1111发送请求...
[12/09/22 10:34:10] 数据库处理出错:no such table: black_list
[12/09/22 10:34:10] 本地数据库读取错误:{'status': 200, 'data': []}
[12/09/22 10:34:20] 向所有服务器发送同步云黑请求...
[12/09/22 10:34:20] 向服务器127.0.0.1:1111发送请求...
[12/09/22 10:34:20] 数据库处理出错:no such table: black_list
[12/09/22 10:34:20] 本地数据库读取错误:{'status': 200, 'data': []}
[12/09/22 10:34:30] 向所有服务器发送同步云黑请求...
[12/09/22 10:34:30] 向服务器127.0.0.1:1111发送请求...
[12/09/22 10:34:30] 数据库处理出错:no such table: black_list
[12/09/22 10:34:30] 本地数据库读取错误:{'status': 200, 'data': []}
[12/09/22 10:34:40] 向所有服务器发送同步云黑请求...
[12/09/22 10:34:40] 向服务器127.0.0.1:1111发送请求...
[12/09/22 10:34:40] 数据库处理出错:no such table: black_list
[12/09/22 10:34:40] 本地数据库读取错误:{'status': 200, 'data': []}
[12/09/22 10:34:50] 向所有服务器发送同步云黑请求...
[12/09/22 10:34:50] 向服务器127.0.0.1:1111发送请求...
[12/09/22 10:34:50] 数据库处理结果:[]
[12/09/22 10:34:50] 本地云黑数据:[]
远程云黑数据:[]
并集数据:[]

[12/09/22 10:34:50] 数据库处理结果:[]
[12/09/22 10:35:00] 向所有服务器发送同步云黑请求...
[12/09/22 10:35:00] 向服务器127.0.0.1:1111发送请求...
[12/09/22 10:35:00] 数据库处理结果:[]
[12/09/22 10:35:00] 本地云黑数据:[]
远程云黑数据:[]
并集数据:[]

[12/09/22 10:35:00] 数据库处理结果:[]
[12/09/22 10:35:10] 向所有服务器发送同步云黑请求...
[12/09/22 10:35:10] 向服务器127.0.0.1:1111发送请求...
[12/09/22 10:35:12] 服务器连接出错:HTTPConnectionPool(host='127.0.0.1', port=1111): Max retries exceeded with url: /blacklist/sync/ (Caused by NewConnectionError('<urllib3.connection.HTTPConnection object at 0x000001DC1E86D150>: Failed to establish a new connection: [WinError 10061] 由于目标计算机积极拒绝，无法连接。'))
Traceback (most recent call last):
  File "C:\Users\zjq13\AppData\Local\Programs\Python\Python311\Lib\site-packages\urllib3\connection.py", line 174, in _new_conn
    conn = connection.create_connection(
           ^^^^^^^^^^^^^^^^^^^^^^^^^^^^^
  File "C:\Users\zjq13\AppData\Local\Programs\Python\Python311\Lib\site-packages\urllib3\util\connection.py", line 95, in create_connection
    raise err
  File "C:\Users\zjq13\AppData\Local\Programs\Python\Python311\Lib\site-packages\urllib3\util\connection.py", line 85, in create_connection
    sock.connect(sa)
ConnectionRefusedError: [WinError 10061] 由于目标计算机积极拒绝，无法连接。

During handling of the above exception, another exception occurred:

Traceback (most recent call last):
  File "C:\Users\zjq13\AppData\Local\Programs\Python\Python311\Lib\site-packages\urllib3\connectionpool.py", line 703, in urlopen
    httplib_response = self._make_request(
                       ^^^^^^^^^^^^^^^^^^^
  File "C:\Users\zjq13\AppData\Local\Programs\Python\Python311\Lib\site-packages\urllib3\connectionpool.py", line 398, in _make_request
    conn.request(method, url, **httplib_request_kw)
  File "C:\Users\zjq13\AppData\Local\Programs\Python\Python311\Lib\site-packages\urllib3\connection.py", line 239, in request
    super(HTTPConnection, self).request(method, url, body=body, headers=headers)
  File "C:\Users\zjq13\AppData\Local\Programs\Python\Python311\Lib\http\client.py", line 1282, in request
    self._send_request(method, url, body, headers, encode_chunked)
  File "C:\Users\zjq13\AppData\Local\Programs\Python\Python311\Lib\http\client.py", line 1328, in _send_request
    self.endheaders(body, encode_chunked=encode_chunked)
  File "C:\Users\zjq13\AppData\Local\Programs\Python\Python311\Lib\http\client.py", line 1277, in endheaders
    self._send_output(message_body, encode_chunked=encode_chunked)
  File "C:\Users\zjq13\AppData\Local\Programs\Python\Python311\Lib\http\client.py", line 1037, in _send_output
    self.send(msg)
  File "C:\Users\zjq13\AppData\Local\Programs\Python\Python311\Lib\http\client.py", line 975, in send
    self.connect()
  File "C:\Users\zjq13\AppData\Local\Programs\Python\Python311\Lib\site-packages\urllib3\connection.py", line 205, in connect
    conn = self._new_conn()
           ^^^^^^^^^^^^^^^^
  File "C:\Users\zjq13\AppData\Local\Programs\Python\Python311\Lib\site-packages\urllib3\connection.py", line 186, in _new_conn
    raise NewConnectionError(
urllib3.exceptions.NewConnectionError: <urllib3.connection.HTTPConnection object at 0x000001DC1E86D150>: Failed to establish a new connection: [WinError 10061] 由于目标计算机积极拒绝，无法连接。

During handling of the above exception, another exception occurred:

Traceback (most recent call last):
  File "C:\Users\zjq13\AppData\Local\Programs\Python\Python311\Lib\site-packages\requests\adapters.py", line 489, in send
    resp = conn.urlopen(
           ^^^^^^^^^^^^^
  File "C:\Users\zjq13\AppData\Local\Programs\Python\Python311\Lib\site-packages\urllib3\connectionpool.py", line 787, in urlopen
    retries = retries.increment(
              ^^^^^^^^^^^^^^^^^^
  File "C:\Users\zjq13\AppData\Local\Programs\Python\Python311\Lib\site-packages\urllib3\util\retry.py", line 592, in increment
    raise MaxRetryError(_pool, url, error or ResponseError(cause))
urllib3.exceptions.MaxRetryError: HTTPConnectionPool(host='127.0.0.1', port=1111): Max retries exceeded with url: /blacklist/sync/ (Caused by NewConnectionError('<urllib3.connection.HTTPConnection object at 0x000001DC1E86D150>: Failed to establish a new connection: [WinError 10061] 由于目标计算机积极拒绝，无法连接。'))

During handling of the above exception, another exception occurred:

Traceback (most recent call last):
  File "E:\zjq13\Documents\GitHub\bread_dog_bot\blacklist_server\main.py", line 153, in sync_all
    r = get(f"http://{s}/blacklist/sync/")
        ^^^^^^^^^^^^^^^^^^^^^^^^^^^^^^^^^^
  File "C:\Users\zjq13\AppData\Local\Programs\Python\Python311\Lib\site-packages\requests\api.py", line 73, in get
    return request("get", url, params=params, **kwargs)
           ^^^^^^^^^^^^^^^^^^^^^^^^^^^^^^^^^^^^^^^^^^^^
  File "C:\Users\zjq13\AppData\Local\Programs\Python\Python311\Lib\site-packages\requests\api.py", line 59, in request
    return session.request(method=method, url=url, **kwargs)
           ^^^^^^^^^^^^^^^^^^^^^^^^^^^^^^^^^^^^^^^^^^^^^^^^^
  File "C:\Users\zjq13\AppData\Local\Programs\Python\Python311\Lib\site-packages\requests\sessions.py", line 587, in request
    resp = self.send(prep, **send_kwargs)
           ^^^^^^^^^^^^^^^^^^^^^^^^^^^^^^
  File "C:\Users\zjq13\AppData\Local\Programs\Python\Python311\Lib\site-packages\requests\sessions.py", line 701, in send
    r = adapter.send(request, **kwargs)
        ^^^^^^^^^^^^^^^^^^^^^^^^^^^^^^^
  File "C:\Users\zjq13\AppData\Local\Programs\Python\Python311\Lib\site-packages\requests\adapters.py", line 565, in send
    raise ConnectionError(e, request=request)
requests.exceptions.ConnectionError: HTTPConnectionPool(host='127.0.0.1', port=1111): Max retries exceeded with url: /blacklist/sync/ (Caused by NewConnectionError('<urllib3.connection.HTTPConnection object at 0x000001DC1E86D150>: Failed to establish a new connection: [WinError 10061] 由于目标计算机积极拒绝，无法连接。'))
[12/09/22 10:35:22] 向所有服务器发送同步云黑请求...
[12/09/22 10:35:22] 向服务器127.0.0.1:1111发送请求...
[12/09/22 10:35:24] 服务器连接出错:HTTPConnectionPool(host='127.0.0.1', port=1111): Max retries exceeded with url: /blacklist/sync/ (Caused by NewConnectionError('<urllib3.connection.HTTPConnection object at 0x000001DC1E86C090>: Failed to establish a new connection: [WinError 10061] 由于目标计算机积极拒绝，无法连接。'))
Traceback (most recent call last):
  File "C:\Users\zjq13\AppData\Local\Programs\Python\Python311\Lib\site-packages\urllib3\connection.py", line 174, in _new_conn
    conn = connection.create_connection(
           ^^^^^^^^^^^^^^^^^^^^^^^^^^^^^
  File "C:\Users\zjq13\AppData\Local\Programs\Python\Python311\Lib\site-packages\urllib3\util\connection.py", line 95, in create_connection
    raise err
  File "C:\Users\zjq13\AppData\Local\Programs\Python\Python311\Lib\site-packages\urllib3\util\connection.py", line 85, in create_connection
    sock.connect(sa)
ConnectionRefusedError: [WinError 10061] 由于目标计算机积极拒绝，无法连接。

During handling of the above exception, another exception occurred:

Traceback (most recent call last):
  File "C:\Users\zjq13\AppData\Local\Programs\Python\Python311\Lib\site-packages\urllib3\connectionpool.py", line 703, in urlopen
    httplib_response = self._make_request(
                       ^^^^^^^^^^^^^^^^^^^
  File "C:\Users\zjq13\AppData\Local\Programs\Python\Python311\Lib\site-packages\urllib3\connectionpool.py", line 398, in _make_request
    conn.request(method, url, **httplib_request_kw)
  File "C:\Users\zjq13\AppData\Local\Programs\Python\Python311\Lib\site-packages\urllib3\connection.py", line 239, in request
    super(HTTPConnection, self).request(method, url, body=body, headers=headers)
  File "C:\Users\zjq13\AppData\Local\Programs\Python\Python311\Lib\http\client.py", line 1282, in request
    self._send_request(method, url, body, headers, encode_chunked)
  File "C:\Users\zjq13\AppData\Local\Programs\Python\Python311\Lib\http\client.py", line 1328, in _send_request
    self.endheaders(body, encode_chunked=encode_chunked)
  File "C:\Users\zjq13\AppData\Local\Programs\Python\Python311\Lib\http\client.py", line 1277, in endheaders
    self._send_output(message_body, encode_chunked=encode_chunked)
  File "C:\Users\zjq13\AppData\Local\Programs\Python\Python311\Lib\http\client.py", line 1037, in _send_output
    self.send(msg)
  File "C:\Users\zjq13\AppData\Local\Programs\Python\Python311\Lib\http\client.py", line 975, in send
    self.connect()
  File "C:\Users\zjq13\AppData\Local\Programs\Python\Python311\Lib\site-packages\urllib3\connection.py", line 205, in connect
    conn = self._new_conn()
           ^^^^^^^^^^^^^^^^
  File "C:\Users\zjq13\AppData\Local\Programs\Python\Python311\Lib\site-packages\urllib3\connection.py", line 186, in _new_conn
    raise NewConnectionError(
urllib3.exceptions.NewConnectionError: <urllib3.connection.HTTPConnection object at 0x000001DC1E86C090>: Failed to establish a new connection: [WinError 10061] 由于目标计算机积极拒绝，无法连接。

During handling of the above exception, another exception occurred:

Traceback (most recent call last):
  File "C:\Users\zjq13\AppData\Local\Programs\Python\Python311\Lib\site-packages\requests\adapters.py", line 489, in send
    resp = conn.urlopen(
           ^^^^^^^^^^^^^
  File "C:\Users\zjq13\AppData\Local\Programs\Python\Python311\Lib\site-packages\urllib3\connectionpool.py", line 787, in urlopen
    retries = retries.increment(
              ^^^^^^^^^^^^^^^^^^
  File "C:\Users\zjq13\AppData\Local\Programs\Python\Python311\Lib\site-packages\urllib3\util\retry.py", line 592, in increment
    raise MaxRetryError(_pool, url, error or ResponseError(cause))
urllib3.exceptions.MaxRetryError: HTTPConnectionPool(host='127.0.0.1', port=1111): Max retries exceeded with url: /blacklist/sync/ (Caused by NewConnectionError('<urllib3.connection.HTTPConnection object at 0x000001DC1E86C090>: Failed to establish a new connection: [WinError 10061] 由于目标计算机积极拒绝，无法连接。'))

During handling of the above exception, another exception occurred:

Traceback (most recent call last):
  File "E:\zjq13\Documents\GitHub\bread_dog_bot\blacklist_server\main.py", line 153, in sync_all
    r = get(f"http://{s}/blacklist/sync/")
        ^^^^^^^^^^^^^^^^^^^^^^^^^^^^^^^^^^
  File "C:\Users\zjq13\AppData\Local\Programs\Python\Python311\Lib\site-packages\requests\api.py", line 73, in get
    return request("get", url, params=params, **kwargs)
           ^^^^^^^^^^^^^^^^^^^^^^^^^^^^^^^^^^^^^^^^^^^^
  File "C:\Users\zjq13\AppData\Local\Programs\Python\Python311\Lib\site-packages\requests\api.py", line 59, in request
    return session.request(method=method, url=url, **kwargs)
           ^^^^^^^^^^^^^^^^^^^^^^^^^^^^^^^^^^^^^^^^^^^^^^^^^
  File "C:\Users\zjq13\AppData\Local\Programs\Python\Python311\Lib\site-packages\requests\sessions.py", line 587, in request
    resp = self.send(prep, **send_kwargs)
           ^^^^^^^^^^^^^^^^^^^^^^^^^^^^^^
  File "C:\Users\zjq13\AppData\Local\Programs\Python\Python311\Lib\site-packages\requests\sessions.py", line 701, in send
    r = adapter.send(request, **kwargs)
        ^^^^^^^^^^^^^^^^^^^^^^^^^^^^^^^
  File "C:\Users\zjq13\AppData\Local\Programs\Python\Python311\Lib\site-packages\requests\adapters.py", line 565, in send
    raise ConnectionError(e, request=request)
requests.exceptions.ConnectionError: HTTPConnectionPool(host='127.0.0.1', port=1111): Max retries exceeded with url: /blacklist/sync/ (Caused by NewConnectionError('<urllib3.connection.HTTPConnection object at 0x000001DC1E86C090>: Failed to establish a new connection: [WinError 10061] 由于目标计算机积极拒绝，无法连接。'))
[12/09/22 10:35:34] 向所有服务器发送同步云黑请求...
[12/09/22 10:35:34] 向服务器127.0.0.1:1111发送请求...
[12/09/22 10:35:34] 数据库处理结果:[]
[12/09/22 10:35:34] 本地云黑数据:[]
远程云黑数据:[]
并集数据:[]

[12/09/22 10:35:34] 数据库处理结果:[]
[12/09/22 10:35:43] 接收到GET请求:http://127.0.0.1:5432/
[12/09/22 10:35:43] 请求者IP为:127.0.0.1
[12/09/22 10:35:43] 接收到同步云黑数据库请求...
[12/09/22 10:35:43] 数据库处理结果:[]
[12/09/22 10:35:43] 同步云黑数据请求成功...
[12/09/22 10:35:44] 向所有服务器发送同步云黑请求...
[12/09/22 10:35:44] 向服务器127.0.0.1:1111发送请求...
[12/09/22 10:35:44] 数据库处理结果:[]
[12/09/22 10:35:44] 本地云黑数据:[]
远程云黑数据:[]
并集数据:[]

[12/09/22 10:35:44] 数据库处理结果:[]
[12/09/22 10:35:53] 接收到GET请求:http://127.0.0.1:5432/
[12/09/22 10:35:53] 请求者IP为:127.0.0.1
[12/09/22 10:35:53] 接收到同步云黑数据库请求...
[12/09/22 10:35:53] 数据库处理结果:[]
[12/09/22 10:35:53] 同步云黑数据请求成功...
[12/09/22 10:35:54] 向所有服务器发送同步云黑请求...
[12/09/22 10:35:54] 向服务器127.0.0.1:1111发送请求...
[12/09/22 10:35:54] 数据库处理结果:[]
[12/09/22 10:35:54] 本地云黑数据:[]
远程云黑数据:[]
并集数据:[]

[12/09/22 10:35:54] 数据库处理结果:[]
[12/09/22 10:36:03] 接收到GET请求:http://127.0.0.1:5432/
[12/09/22 10:36:03] 请求者IP为:127.0.0.1
[12/09/22 10:36:03] 接收到同步云黑数据库请求...
[12/09/22 10:36:03] 数据库处理结果:[]
[12/09/22 10:36:03] 同步云黑数据请求成功...
[12/09/22 10:36:04] 向所有服务器发送同步云黑请求...
[12/09/22 10:36:04] 向服务器127.0.0.1:1111发送请求...
[12/09/22 10:36:04] 数据库处理结果:[]
[12/09/22 10:36:04] 本地云黑数据:[]
远程云黑数据:[]
并集数据:[]

[12/09/22 10:36:04] 数据库处理结果:[]
[12/09/22 10:36:13] 接收到GET请求:http://127.0.0.1:5432/
[12/09/22 10:36:13] 请求者IP为:127.0.0.1
[12/09/22 10:36:13] 接收到同步云黑数据库请求...
[12/09/22 10:36:13] 数据库处理结果:[]
[12/09/22 10:36:13] 同步云黑数据请求成功...
[12/09/22 10:36:14] 向所有服务器发送同步云黑请求...
[12/09/22 10:36:14] 向服务器127.0.0.1:1111发送请求...
[12/09/22 10:36:14] 数据库处理结果:[]
[12/09/22 10:36:14] 本地云黑数据:[]
远程云黑数据:[]
并集数据:[]

[12/09/22 10:36:14] 数据库处理结果:[]
[12/09/22 10:36:23] 接收到GET请求:http://127.0.0.1:5432/
[12/09/22 10:36:23] 请求者IP为:127.0.0.1
[12/09/22 10:36:23] 接收到同步云黑数据库请求...
[12/09/22 10:36:23] 数据库处理结果:[]
[12/09/22 10:36:23] 同步云黑数据请求成功...
[12/09/22 10:36:24] 向所有服务器发送同步云黑请求...
[12/09/22 10:36:24] 向服务器127.0.0.1:1111发送请求...
[12/09/22 10:36:24] 数据库处理结果:[]
[12/09/22 10:36:24] 本地云黑数据:[]
远程云黑数据:[]
并集数据:[]

[12/09/22 10:36:24] 数据库处理结果:[]
[12/09/22 10:36:33] 接收到GET请求:http://127.0.0.1:5432/
[12/09/22 10:36:33] 请求者IP为:127.0.0.1
[12/09/22 10:36:33] 接收到同步云黑数据库请求...
[12/09/22 10:36:33] 数据库处理结果:[]
[12/09/22 10:36:33] 同步云黑数据请求成功...
[12/09/22 10:36:34] 向所有服务器发送同步云黑请求...
[12/09/22 10:36:34] 向服务器127.0.0.1:1111发送请求...
[12/09/22 10:36:34] 数据库处理结果:[]
[12/09/22 10:36:34] 本地云黑数据:[]
远程云黑数据:[]
并集数据:[]

[12/09/22 10:36:34] 数据库处理结果:[]
[12/09/22 10:36:43] 接收到GET请求:http://127.0.0.1:5432/
[12/09/22 10:36:43] 请求者IP为:127.0.0.1
[12/09/22 10:36:43] 接收到同步云黑数据库请求...
[12/09/22 10:36:43] 数据库处理结果:[]
[12/09/22 10:36:43] 同步云黑数据请求成功...
[12/09/22 10:36:44] 向所有服务器发送同步云黑请求...
[12/09/22 10:36:44] 向服务器127.0.0.1:1111发送请求...
[12/09/22 10:36:44] 数据库处理结果:[]
[12/09/22 10:36:44] 本地云黑数据:[]
远程云黑数据:[]
并集数据:[]

[12/09/22 10:36:44] 数据库处理结果:[]
[12/09/22 10:36:53] 接收到GET请求:http://127.0.0.1:5432/
[12/09/22 10:36:53] 请求者IP为:127.0.0.1
[12/09/22 10:36:53] 接收到同步云黑数据库请求...
[12/09/22 10:36:53] 数据库处理结果:[]
[12/09/22 10:36:53] 同步云黑数据请求成功...
[12/09/22 10:36:54] 向所有服务器发送同步云黑请求...
[12/09/22 10:36:54] 向服务器127.0.0.1:1111发送请求...
[12/09/22 10:36:54] 数据库处理结果:[]
[12/09/22 10:36:54] 本地云黑数据:[]
远程云黑数据:[]
并集数据:[]

[12/09/22 10:36:54] 数据库处理结果:[]
[12/09/22 10:37:03] 接收到GET请求:http://127.0.0.1:5432/
[12/09/22 10:37:03] 请求者IP为:127.0.0.1
[12/09/22 10:37:03] 接收到同步云黑数据库请求...
[12/09/22 10:37:03] 数据库处理结果:[('222', '5555', 'test')]
[12/09/22 10:37:03] 同步云黑数据请求成功...
[12/09/22 10:37:05] 向所有服务器发送同步云黑请求...
[12/09/22 10:37:05] 向服务器127.0.0.1:1111发送请求...
[12/09/22 10:37:05] 数据库处理结果:[('222', '5555', 'test')]
[12/09/22 10:37:05] 本地云黑数据:[('222', '5555', 'test')]
远程云黑数据:[['222', '5555', 'test']]
并集数据:[['222', '5555', 'test']]

[12/09/22 10:37:05] 数据库处理结果:[]
[12/09/22 10:37:14] 接收到GET请求:http://127.0.0.1:5432/
[12/09/22 10:37:14] 请求者IP为:127.0.0.1
[12/09/22 10:37:14] 接收到同步云黑数据库请求...
[12/09/22 10:37:14] 数据库处理结果:[('222', '5555', 'test'), ('222', '5555', 'test')]
[12/09/22 10:37:14] 同步云黑数据请求成功...
[12/09/22 10:37:15] 向所有服务器发送同步云黑请求...
[12/09/22 10:37:15] 向服务器127.0.0.1:1111发送请求...
[12/09/22 10:37:15] 数据库处理结果:[('222', '5555', 'test'), ('222', '5555', 'test')]
[12/09/22 10:37:15] 本地云黑数据:[('222', '5555', 'test'), ('222', '5555', 'test')]
远程云黑数据:[['222', '5555', 'test'], ['222', '5555', 'test'], ['222', '5555', 'test']]
并集数据:[['222', '5555', 'test'], ['222', '5555', 'test'], ['222', '5555', 'test']]

[12/09/22 10:37:15] 数据库处理结果:[]
[12/09/22 10:37:24] 接收到GET请求:http://127.0.0.1:5432/
[12/09/22 10:37:24] 请求者IP为:127.0.0.1
[12/09/22 10:37:24] 接收到同步云黑数据库请求...
[12/09/22 10:37:24] 数据库处理结果:[('222', '5555', 'test'), ('222', '5555', 'test'), ('222', '5555', 'test'), ('222', '5555', 'test'), ('222', '5555', 'test')]
[12/09/22 10:37:24] 同步云黑数据请求成功...
[12/09/22 10:37:25] 向所有服务器发送同步云黑请求...
[12/09/22 10:37:25] 向服务器127.0.0.1:1111发送请求...
[12/09/22 10:37:25] 数据库处理结果:[('222', '5555', 'test'), ('222', '5555', 'test'), ('222', '5555', 'test'), ('222', '5555', 'test'), ('222', '5555', 'test')]
[12/09/22 10:37:25] 本地云黑数据:[('222', '5555', 'test'), ('222', '5555', 'test'), ('222', '5555', 'test'), ('222', '5555', 'test'), ('222', '5555', 'test')]
远程云黑数据:[['222', '5555', 'test'], ['222', '5555', 'test'], ['222', '5555', 'test'], ['222', '5555', 'test'], ['222', '5555', 'test'], ['222', '5555', 'test'], ['222', '5555', 'test'], ['222', '5555', 'test']]
并集数据:[['222', '5555', 'test'], ['222', '5555', 'test'], ['222', '5555', 'test'], ['222', '5555', 'test'], ['222', '5555', 'test'], ['222', '5555', 'test'], ['222', '5555', 'test'], ['222', '5555', 'test']]

[12/09/22 10:37:25] 数据库处理结果:[]
